Workbook
Name ActiveColors: OFFSET(Settings!$I$3,0,0,Settings!$B$3,1)
Name ActivePlayers: OFFSET(Settings!$E$3,0,0,Settings!$B$3,1)

Sheet Settings
A1: Mario Super Sluggers Tournament Settings
A2: Current Tournament Number | B2: 1 | D2: Slot | E2: Player Name | F2: Status | G2: In Tournament? | I2: Color Slot | J2: Seed | K2: Seeded Player | L2: Check | N2: Draft Slot | O2: Drafting Player | P2: Check
A3: Player Count | B3: 6 | D3: =IF(1<=$B$3,1,"") -> 1 | E3: Aidan | F3: =IF(1<=$B$3,IF(D3<=$B$3,"Active","Inactive"),"") -> Active | G3: =IF(1<=$B$3,D3<=$B$3,"") -> TRUE | I3: Blue | J3: =IF(1<=$B$3,1,"") -> 1 | K3: May | L3: =IF($J3="","",IF(K3="","Select player",IF(COUNTIF($K$3:$K$10,K3)>1,"Duplicate",""))) | N3: =IF(1<=$B$3,1,"") -> 1 | O3: Justin | P3: =IF($N3="","",IF(O3="","Select player",IF(COUNTIF($O$3:$O$10,O3)>1,"Duplicate","")))
A4: Tournament Date | D4: =IF(2<=$B$3,2,"") -> 2 | E4: Donovan | F4: =IF(2<=$B$3,IF(D4<=$B$3,"Active","Inactive"),"") -> Active | G4: =IF(2<=$B$3,D4<=$B$3,"") -> TRUE | I4: Orange | J4: =IF(2<=$B$3,2,"") -> 2 | K4: Jason | L4: =IF($J4="","",IF(K4="","Select player",IF(COUNTIF($K$3:$K$10,K4)>1,"Duplicate",""))) | N4: =IF(2<=$B$3,2,"") -> 2 | O4: Donovan | P4: =IF($N4="","",IF(O4="","Select player",IF(COUNTIF($O$3:$O$10,O4)>1,"Duplicate","")))
A5: Notes | D5: =IF(3<=$B$3,3,"") -> 3 | E5: Jason | F5: =IF(3<=$B$3,IF(D5<=$B$3,"Active","Inactive"),"") -> Active | G5: =IF(3<=$B$3,D5<=$B$3,"") -> TRUE | I5: Green | J5: =IF(3<=$B$3,3,"") -> 3 | K5: Aidan | L5: =IF($J5="","",IF(K5="","Select player",IF(COUNTIF($K$3:$K$10,K5)>1,"Duplicate",""))) | N5: =IF(3<=$B$3,3,"") -> 3 | O5: Nick | P5: =IF($N5="","",IF(O5="","Select player",IF(COUNTIF($O$3:$O$10,O5)>1,"Duplicate","")))
D6: =IF(4<=$B$3,4,"") -> 4 | E6: Justin | F6: =IF(4<=$B$3,IF(D6<=$B$3,"Active","Inactive"),"") -> Active | G6: =IF(4<=$B$3,D6<=$B$3,"") -> TRUE | I6: Red | J6: =IF(4<=$B$3,4,"") -> 4 | K6: Nick | L6: =IF($J6="","",IF(K6="","Select player",IF(COUNTIF($K$3:$K$10,K6)>1,"Duplicate",""))) | N6: =IF(4<=$B$3,4,"") -> 4 | O6: Aidan | P6: =IF($N6="","",IF(O6="","Select player",IF(COUNTIF($O$3:$O$10,O6)>1,"Duplicate","")))
D7: =IF(5<=$B$3,5,"") -> 5 | E7: May | F7: =IF(5<=$B$3,IF(D7<=$B$3,"Active","Inactive"),"") -> Active | G7: =IF(5<=$B$3,D7<=$B$3,"") -> TRUE | I7: Purple | J7: =IF(5<=$B$3,5,"") -> 5 | K7: Donovan | L7: =IF($J7="","",IF(K7="","Select player",IF(COUNTIF($K$3:$K$10,K7)>1,"Duplicate",""))) | N7: =IF(5<=$B$3,5,"") -> 5 | O7: Jason | P7: =IF($N7="","",IF(O7="","Select player",IF(COUNTIF($O$3:$O$10,O7)>1,"Duplicate","")))
D8: =IF(6<=$B$3,6,"") -> 6 | E8: Nick | F8: =IF(6<=$B$3,IF(D8<=$B$3,"Active","Inactive"),"") -> Active | G8: =IF(6<=$B$3,D8<=$B$3,"") -> TRUE | I8: Pink | J8: =IF(6<=$B$3,6,"") -> 6 | K8: Justin | L8: =IF($J8="","",IF(K8="","Select player",IF(COUNTIF($K$3:$K$10,K8)>1,"Duplicate",""))) | N8: =IF(6<=$B$3,6,"") -> 6 | O8: May | P8: =IF($N8="","",IF(O8="","Select player",IF(COUNTIF($O$3:$O$10,O8)>1,"Duplicate","")))
D9: =IF(7<=$B$3,7,"") | E9: Player 7 | F9: =IF(7<=$B$3,IF(D9<=$B$3,"Active","Inactive"),"") | G9: =IF(7<=$B$3,D9<=$B$3,"") | I9: Gray | J9: =IF(7<=$B$3,7,"") | L9: =IF($J9="","",IF(K9="","Select player",IF(COUNTIF($K$3:$K$10,K9)>1,"Duplicate",""))) | N9: =IF(7<=$B$3,7,"") | P9: =IF($N9="","",IF(O9="","Select player",IF(COUNTIF($O$3:$O$10,O9)>1,"Duplicate","")))
D10: =IF(8<=$B$3,8,"") | E10: Player 8 | F10: =IF(8<=$B$3,IF(D10<=$B$3,"Active","Inactive"),"") | G10: =IF(8<=$B$3,D10<=$B$3,"") | I10: Brown | J10: =IF(8<=$B$3,8,"") | L10: =IF($J10="","",IF(K10="","Select player",IF(COUNTIF($K$3:$K$10,K10)>1,"Duplicate",""))) | N10: =IF(8<=$B$3,8,"") | P10: =IF($N10="","",IF(O10="","Select player",IF(COUNTIF($O$3:$O$10,O10)>1,"Duplicate","")))

Sheet Draft
A1: Current Tournament Draft
A3: Tournament | B3: =Settings!$B$2 -> 1 | C3: Player Count | D3: =Settings!$B$3 -> 6 | E3: Total Picks | F3: =Settings!$B$3*9 -> 54 | H3: Current Rosters
A5: Pick # | B5: Round | C5: Pick in Rd | D5: Drafting Player | E5: Character | H5: =IF(1<=Settings!$B$3,Settings!$E$3,"") -> Aidan | I5: =IF(2<=Settings!$B$3,Settings!$E$4,"") -> Donovan | J5: =IF(3<=Settings!$B$3,Settings!$E$5,"") -> Jason | K5: =IF(4<=Settings!$B$3,Settings!$E$6,"") -> Justin | L5: =IF(5<=Settings!$B$3,Settings!$E$7,"") -> May | M5: =IF(6<=Settings!$B$3,Settings!$E$8,"") -> Nick | N5: =IF(7<=Settings!$B$3,Settings!$E$9,"") | O5: =IF(8<=Settings!$B$3,Settings!$E$10,"")
A6: =IF(ROW()-5<=$F$3,ROW()-5,"") -> 1 | B6: =IF($A6="","",ROUNDUP($A6/$D$3,0)) -> 1 | C6: =IF($A6="","",MOD($A6-1,$D$3)+1) -> 1 | D6: =IF($A6="","",IF(MOD($B6,2)=1,INDEX(Settings!$O$3:$O$10,$C6),INDEX(Settings!$O$3:$O$10,$D$3-$C6+1))) -> Justin | E6: Bowser Jr. | H6: {=IF(H$5="","",IFERROR(_xlfn.LET(_xlpm.x,_xlfn.SINGLE(INDEX(_xlfn._xlws.FILTER($E$6:$E$77,$D$6:$D$77=H$5),ROWS(H$6:H6))),IF(_xlpm.x=0,"",_xlpm.x)),""))} -> Mario | I6: {=IF(I$5="","",IFERROR(_xlfn.LET(_xlpm.x,_xlfn.SINGLE(INDEX(_xlfn._xlws.FILTER($E$6:$E$77,$D$6:$D$77=I$5),ROWS(I$6:I6))),IF(_xlpm.x=0,"",_xlpm.x)),""))} -> Donkey Kong | J6: {=IF(J$5="","",IFERROR(_xlfn.LET(_xlpm.x,_xlfn.SINGLE(INDEX(_xlfn._xlws.FILTER($E$6:$E$77,$D$6:$D$77=J$5),ROWS(J$6:J6))),IF(_xlpm.x=0,"",_xlpm.x)),""))} -> Bowser | K6: {=IF(K$5="","",IFERROR(_xlfn.LET(_xlpm.x,_xlfn.SINGLE(INDEX(_xlfn._xlws.FILTER($E$6:$E$77,$D$6:$D$77=K$5),ROWS(K$6:K6))),IF(_xlpm.x=0,"",_xlpm.x)),""))} -> Bowser Jr. | L6: {=IF(L$5="","",IFERROR(_xlfn.LET(_xlpm.x,_xlfn.SINGLE(INDEX(_xlfn._xlws.FILTER($E$6:$E$77,$D$6:$D$77=L$5),ROWS(L$6:L6))),IF(_xlpm.x=0,"",_xlpm.x)),""))} -> Birdo | M6: {=IF(M$5="","",IFERROR(_xlfn.LET(_xlpm.x,_xlfn.SINGLE(INDEX(_xlfn._xlws.FILTER($E$6:$E$77,$D$6:$D$77=M$5),ROWS(M$6:M6))),IF(_xlpm.x=0,"",_xlpm.x)),""))} -> Daisy | N6: {=IF(N$5="","",IFERROR(_xlfn.LET(_xlpm.x,_xlfn.SINGLE(INDEX(_xlfn._xlws.FILTER($E$6:$E$77,$D$6:$D$77=N$5),ROWS(N$6:N6))),IF(_xlpm.x=0,"",_xlpm.x)),""))} | O6: {=IF(O$5="","",IFERROR(_xlfn.LET(_xlpm.x,_xlfn.SINGLE(INDEX(_xlfn._xlws.FILTER($E$6:$E$77,$D$6:$D$77=O$5),ROWS(O$6:O6))),IF(_xlpm.x=0,"",_xlpm.x)),""))}
A7: =IF(ROW()-5<=$F$3,ROW()-5,"") -> 2 | B7: =IF($A7="","",ROUNDUP($A7/$D$3,0)) -> 1 | C7: =IF($A7="","",MOD($A7-1,$D$3)+1) -> 2 | D7: =IF($A7="","",IF(MOD($B7,2)=1,INDEX(Settings!$O$3:$O$10,$C7),INDEX(Settings!$O$3:$O$10,$D$3-$C7+1))) -> Donovan | E7: Donkey Kong | H7: {=IF(H$5="","",IFERROR(_xlfn.LET(_xlpm.x,_xlfn.SINGLE(INDEX(_xlfn._xlws.FILTER($E$6:$E$77,$D$6:$D$77=H$5),ROWS(H$6:H7))),IF(_xlpm.x=0,"",_xlpm.x)),""))} -> Luigi | I7: {=IF(I$5="","",IFERROR(_xlfn.LET(_xlpm.x,_xlfn.SINGLE(INDEX(_xlfn._xlws.FILTER($E$6:$E$77,$D$6:$D$77=I$5),ROWS(I$6:I7))),IF(_xlpm.x=0,"",_xlpm.x)),""))} -> Waluigi | J7: {=IF(J$5="","",IFERROR(_xlfn.LET(_xlpm.x,_xlfn.SINGLE(INDEX(_xlfn._xlws.FILTER($E$6:$E$77,$D$6:$D$77=J$5),ROWS(J$6:J7))),IF(_xlpm.x=0,"",_xlpm.x)),""))} -> Peach | K7: {=IF(K$5="","",IFERROR(_xlfn.LET(_xlpm.x,_xlfn.SINGLE(INDEX(_xlfn._xlws.FILTER($E$6:$E$77,$D$6:$D$77=K$5),ROWS(K$6:K7))),IF(_xlpm.x=0,"",_xlpm.x)),""))} -> Boo | L7: {=IF(L$5="","",IFERROR(_xlfn.LET(_xlpm.x,_xlfn.SINGLE(INDEX(_xlfn._xlws.FILTER($E$6:$E$77,$D$6:$D$77=L$5),ROWS(L$6:L7))),IF(_xlpm.x=0,"",_xlpm.x)),""))} -> Petey Piranha | M7: {=IF(M$5="","",IFERROR(_xlfn.LET(_xlpm.x,_xlfn.SINGLE(INDEX(_xlfn._xlws.FILTER($E$6:$E$77,$D$6:$D$77=M$5),ROWS(M$6:M7))),IF(_xlpm.x=0,"",_xlpm.x)),""))} -> Mii | N7: {=IF(N$5="","",IFERROR(_xlfn.LET(_xlpm.x,_xlfn.SINGLE(INDEX(_xlfn._xlws.FILTER($E$6:$E$77,$D$6:$D$77=N$5),ROWS(N$6:N7))),IF(_xlpm.x=0,"",_xlpm.x)),""))} | O7: {=IF(O$5="","",IFERROR(_xlfn.LET(_xlpm.x,_xlfn.SINGLE(INDEX(_xlfn._xlws.FILTER($E$6:$E$77,$D$6:$D$77=O$5),ROWS(O$6:O7))),IF(_xlpm.x=0,"",_xlpm.x)),""))}
A8: =IF(ROW()-5<=$F$3,ROW()-5,"") -> 3 | B8: =IF($A8="","",ROUNDUP($A8/$D$3,0)) -> 1 | C8: =IF($A8="","",MOD($A8-1,$D$3)+1) -> 3 | D8: =IF($A8="","",IF(MOD($B8,2)=1,INDEX(Settings!$O$3:$O$10,$C8),INDEX(Settings!$O$3:$O$10,$D$3-$C8+1))) -> Nick | E8: Daisy | H8: {=IF(H$5="","",IFERROR(_xlfn.LET(_xlpm.x,_xlfn.SINGLE(INDEX(_xlfn._xlws.FILTER($E$6:$E$77,$D$6:$D$77=H$5),ROWS(H$6:H8))),IF(_xlpm.x=0,"",_xlpm.x)),""))} -> Dark Bones | I8: {=IF(I$5="","",IFERROR(_xlfn.LET(_xlpm.x,_xlfn.SINGLE(INDEX(_xlfn._xlws.FILTER($E$6:$E$77,$D$6:$D$77=I$5),ROWS(I$6:I8))),IF(_xlpm.x=0,"",_xlpm.x)),""))} -> Diddy Kong | J8: {=IF(J$5="","",IFERROR(_xlfn.LET(_xlpm.x,_xlfn.SINGLE(INDEX(_xlfn._xlws.FILTER($E$6:$E$77,$D$6:$D$77=J$5),ROWS(J$6:J8))),IF(_xlpm.x=0,"",_xlpm.x)),""))} -> Yoshi | K8: {=IF(K$5="","",IFERROR(_xlfn.LET(_xlpm.x,_xlfn.SINGLE(INDEX(_xlfn._xlws.FILTER($E$6:$E$77,$D$6:$D$77=K$5),ROWS(K$6:K8))),IF(_xlpm.x=0,"",_xlpm.x)),""))} -> Funky Kong | L8: {=IF(L$5="","",IFERROR(_xlfn.LET(_xlpm.x,_xlfn.SINGLE(INDEX(_xlfn._xlws.FILTER($E$6:$E$77,$D$6:$D$77=L$5),ROWS(L$6:L8))),IF(_xlpm.x=0,"",_xlpm.x)),""))} -> King Boo | M8: {=IF(M$5="","",IFERROR(_xlfn.LET(_xlpm.x,_xlfn.SINGLE(INDEX(_xlfn._xlws.FILTER($E$6:$E$77,$D$6:$D$77=M$5),ROWS(M$6:M8))),IF(_xlpm.x=0,"",_xlpm.x)),""))} -> Toadette | N8: {=IF(N$5="","",IFERROR(_xlfn.LET(_xlpm.x,_xlfn.SINGLE(INDEX(_xlfn._xlws.FILTER($E$6:$E$77,$D$6:$D$77=N$5),ROWS(N$6:N8))),IF(_xlpm.x=0,"",_xlpm.x)),""))} | O8: {=IF(O$5="","",IFERROR(_xlfn.LET(_xlpm.x,_xlfn.SINGLE(INDEX(_xlfn._xlws.FILTER($E$6:$E$77,$D$6:$D$77=O$5),ROWS(O$6:O8))),IF(_xlpm.x=0,"",_xlpm.x)),""))}
A9: =IF(ROW()-5<=$F$3,ROW()-5,"") -> 4 | B9: =IF($A9="","",ROUNDUP($A9/$D$3,0)) -> 1 | C9: =IF($A9="","",MOD($A9-1,$D$3)+1) -> 4 | D9: =IF($A9="","",IF(MOD($B9,2)=1,INDEX(Settings!$O$3:$O$10,$C9),INDEX(Settings!$O$3:$O$10,$D$3-$C9+1))) -> Aidan | E9: Mario | H9: {=IF(H$5="","",IFERROR(_xlfn.LET(_xlpm.x,_xlfn.SINGLE(INDEX(_xlfn._xlws.FILTER($E$6:$E$77,$D$6:$D$77=H$5),ROWS(H$6:H9))),IF(_xlpm.x=0,"",_xlpm.x)),""))} -> Pink Yoshi | I9: {=IF(I$5="","",IFERROR(_xlfn.LET(_xlpm.x,_xlfn.SINGLE(INDEX(_xlfn._xlws.FILTER($E$6:$E$77,$D$6:$D$77=I$5),ROWS(I$6:I9))),IF(_xlpm.x=0,"",_xlpm.x)),""))} -> Baby DK | J9: {=IF(J$5="","",IFERROR(_xlfn.LET(_xlpm.x,_xlfn.SINGLE(INDEX(_xlfn._xlws.FILTER($E$6:$E$77,$D$6:$D$77=J$5),ROWS(J$6:J9))),IF(_xlpm.x=0,"",_xlpm.x)),""))} -> King K. Rool | K9: {=IF(K$5="","",IFERROR(_xlfn.LET(_xlpm.x,_xlfn.SINGLE(INDEX(_xlfn._xlws.FILTER($E$6:$E$77,$D$6:$D$77=K$5),ROWS(K$6:K9))),IF(_xlpm.x=0,"",_xlpm.x)),""))} -> Yellow Magikoopa | L9: {=IF(L$5="","",IFERROR(_xlfn.LET(_xlpm.x,_xlfn.SINGLE(INDEX(_xlfn._xlws.FILTER($E$6:$E$77,$D$6:$D$77=L$5),ROWS(L$6:L9))),IF(_xlpm.x=0,"",_xlpm.x)),""))} -> Red Kritter | M9: {=IF(M$5="","",IFERROR(_xlfn.LET(_xlpm.x,_xlfn.SINGLE(INDEX(_xlfn._xlws.FILTER($E$6:$E$77,$D$6:$D$77=M$5),ROWS(M$6:M9))),IF(_xlpm.x=0,"",_xlpm.x)),""))} -> Blue Toad | N9: {=IF(N$5="","",IFERROR(_xlfn.LET(_xlpm.x,_xlfn.SINGLE(INDEX(_xlfn._xlws.FILTER($E$6:$E$77,$D$6:$D$77=N$5),ROWS(N$6:N9))),IF(_xlpm.x=0,"",_xlpm.x)),""))} | O9: {=IF(O$5="","",IFERROR(_xlfn.LET(_xlpm.x,_xlfn.SINGLE(INDEX(_xlfn._xlws.FILTER($E$6:$E$77,$D$6:$D$77=O$5),ROWS(O$6:O9))),IF(_xlpm.x=0,"",_xlpm.x)),""))}
A10: =IF(ROW()-5<=$F$3,ROW()-5,"") -> 5 | B10: =IF($A10="","",ROUNDUP($A10/$D$3,0)) -> 1 | C10: =IF($A10="","",MOD($A10-1,$D$3)+1) -> 5 | D10: =IF($A10="","",IF(MOD($B10,2)=1,INDEX(Settings!$O$3:$O$10,$C10),INDEX(Settings!$O$3:$O$10,$D$3-$C10+1))) -> Jason | E10: Bowser | H10: {=IF(H$5="","",IFERROR(_xlfn.LET(_xlpm.x,_xlfn.SINGLE(INDEX(_xlfn._xlws.FILTER($E$6:$E$77,$D$6:$D$77=H$5),ROWS(H$6:H10))),IF(_xlpm.x=0,"",_xlpm.x)),""))} -> Red Magikoopa | I10: {=IF(I$5="","",IFERROR(_xlfn.LET(_xlpm.x,_xlfn.SINGLE(INDEX(_xlfn._xlws.FILTER($E$6:$E$77,$D$6:$D$77=I$5),ROWS(I$6:I10))),IF(_xlpm.x=0,"",_xlpm.x)),""))} -> Dixie Kong | J10: {=IF(J$5="","",IFERROR(_xlfn.LET(_xlpm.x,_xlfn.SINGLE(INDEX(_xlfn._xlws.FILTER($E$6:$E$77,$D$6:$D$77=J$5),ROWS(J$6:J10))),IF(_xlpm.x=0,"",_xlpm.x)),""))} -> Baby Daisy | K10: {=IF(K$5="","",IFERROR(_xlfn.LET(_xlpm.x,_xlfn.SINGLE(INDEX(_xlfn._xlws.FILTER($E$6:$E$77,$D$6:$D$77=K$5),ROWS(K$6:K10))),IF(_xlpm.x=0,"",_xlpm.x)),""))} -> Blue Yoshi | L10: {=IF(L$5="","",IFERROR(_xlfn.LET(_xlpm.x,_xlfn.SINGLE(INDEX(_xlfn._xlws.FILTER($E$6:$E$77,$D$6:$D$77=L$5),ROWS(L$6:L10))),IF(_xlpm.x=0,"",_xlpm.x)),""))} -> Red Yoshi | M10: {=IF(M$5="","",IFERROR(_xlfn.LET(_xlpm.x,_xlfn.SINGLE(INDEX(_xlfn._xlws.FILTER($E$6:$E$77,$D$6:$D$77=M$5),ROWS(M$6:M10))),IF(_xlpm.x=0,"",_xlpm.x)),""))} -> Monty Mole | N10: {=IF(N$5="","",IFERROR(_xlfn.LET(_xlpm.x,_xlfn.SINGLE(INDEX(_xlfn._xlws.FILTER($E$6:$E$77,$D$6:$D$77=N$5),ROWS(N$6:N10))),IF(_xlpm.x=0,"",_xlpm.x)),""))} | O10: {=IF(O$5="","",IFERROR(_xlfn.LET(_xlpm.x,_xlfn.SINGLE(INDEX(_xlfn._xlws.FILTER($E$6:$E$77,$D$6:$D$77=O$5),ROWS(O$6:O10))),IF(_xlpm.x=0,"",_xlpm.x)),""))}
A11: =IF(ROW()-5<=$F$3,ROW()-5,"") -> 6 | B11: =IF($A11="","",ROUNDUP($A11/$D$3,0)) -> 1 | C11: =IF($A11="","",MOD($A11-1,$D$3)+1) -> 6 | D11: =IF($A11="","",IF(MOD($B11,2)=1,INDEX(Settings!$O$3:$O$10,$C11),INDEX(Settings!$O$3:$O$10,$D$3-$C11+1))) -> May | E11: Birdo | H11: {=IF(H$5="","",IFERROR(_xlfn.LET(_xlpm.x,_xlfn.SINGLE(INDEX(_xlfn._xlws.FILTER($E$6:$E$77,$D$6:$D$77=H$5),ROWS(H$6:H11))),IF(_xlpm.x=0,"",_xlpm.x)),""))} -> Blue Pianta | I11: {=IF(I$5="","",IFERROR(_xlfn.LET(_xlpm.x,_xlfn.SINGLE(INDEX(_xlfn._xlws.FILTER($E$6:$E$77,$D$6:$D$77=I$5),ROWS(I$6:I11))),IF(_xlpm.x=0,"",_xlpm.x)),""))} -> Fire Bro | J11: {=IF(J$5="","",IFERROR(_xlfn.LET(_xlpm.x,_xlfn.SINGLE(INDEX(_xlfn._xlws.FILTER($E$6:$E$77,$D$6:$D$77=J$5),ROWS(J$6:J11))),IF(_xlpm.x=0,"",_xlpm.x)),""))} -> Baby Mario | K11: {=IF(K$5="","",IFERROR(_xlfn.LET(_xlpm.x,_xlfn.SINGLE(INDEX(_xlfn._xlws.FILTER($E$6:$E$77,$D$6:$D$77=K$5),ROWS(K$6:K11))),IF(_xlpm.x=0,"",_xlpm.x)),""))} -> Red Pianta | L11: {=IF(L$5="","",IFERROR(_xlfn.LET(_xlpm.x,_xlfn.SINGLE(INDEX(_xlfn._xlws.FILTER($E$6:$E$77,$D$6:$D$77=L$5),ROWS(L$6:L11))),IF(_xlpm.x=0,"",_xlpm.x)),""))} -> Baby Peach | M11: {=IF(M$5="","",IFERROR(_xlfn.LET(_xlpm.x,_xlfn.SINGLE(INDEX(_xlfn._xlws.FILTER($E$6:$E$77,$D$6:$D$77=M$5),ROWS(M$6:M11))),IF(_xlpm.x=0,"",_xlpm.x)),""))} -> Wario | N11: {=IF(N$5="","",IFERROR(_xlfn.LET(_xlpm.x,_xlfn.SINGLE(INDEX(_xlfn._xlws.FILTER($E$6:$E$77,$D$6:$D$77=N$5),ROWS(N$6:N11))),IF(_xlpm.x=0,"",_xlpm.x)),""))} | O11: {=IF(O$5="","",IFERROR(_xlfn.LET(_xlpm.x,_xlfn.SINGLE(INDEX(_xlfn._xlws.FILTER($E$6:$E$77,$D$6:$D$77=O$5),ROWS(O$6:O11))),IF(_xlpm.x=0,"",_xlpm.x)),""))}
A12: =IF(ROW()-5<=$F$3,ROW()-5,"") -> 7 | B12: =IF($A12="","",ROUNDUP($A12/$D$3,0)) -> 2 | C12: =IF($A12="","",MOD($A12-1,$D$3)+1) -> 1 | D12: =IF($A12="","",IF(MOD($B12,2)=1,INDEX(Settings!$O$3:$O$10,$C12),INDEX(Settings!$O$3:$O$10,$D$3-$C12+1))) -> May | E12: Petey Piranha | H12: {=IF(H$5="","",IFERROR(_xlfn.LET(_xlpm.x,_xlfn.SINGLE(INDEX(_xlfn._xlws.FILTER($E$6:$E$77,$D$6:$D$77=H$5),ROWS(H$6:H12))),IF(_xlpm.x=0,"",_xlpm.x)),""))} -> Yellow Pianta | I12: {=IF(I$5="","",IFERROR(_xlfn.LET(_xlpm.x,_xlfn.SINGLE(INDEX(_xlfn._xlws.FILTER($E$6:$E$77,$D$6:$D$77=I$5),ROWS(I$6:I12))),IF(_xlpm.x=0,"",_xlpm.x)),""))} -> Tiny Kong | J12: {=IF(J$5="","",IFERROR(_xlfn.LET(_xlpm.x,_xlfn.SINGLE(INDEX(_xlfn._xlws.FILTER($E$6:$E$77,$D$6:$D$77=J$5),ROWS(J$6:J12))),IF(_xlpm.x=0,"",_xlpm.x)),""))} -> Brown Kritter | K12: {=IF(K$5="","",IFERROR(_xlfn.LET(_xlpm.x,_xlfn.SINGLE(INDEX(_xlfn._xlws.FILTER($E$6:$E$77,$D$6:$D$77=K$5),ROWS(K$6:K12))),IF(_xlpm.x=0,"",_xlpm.x)),""))} -> Baby Luigi | L12: {=IF(L$5="","",IFERROR(_xlfn.LET(_xlpm.x,_xlfn.SINGLE(INDEX(_xlfn._xlws.FILTER($E$6:$E$77,$D$6:$D$77=L$5),ROWS(L$6:L12))),IF(_xlpm.x=0,"",_xlpm.x)),""))} -> Hammer Bro | M12: {=IF(M$5="","",IFERROR(_xlfn.LET(_xlpm.x,_xlfn.SINGLE(INDEX(_xlfn._xlws.FILTER($E$6:$E$77,$D$6:$D$77=M$5),ROWS(M$6:M12))),IF(_xlpm.x=0,"",_xlpm.x)),""))} -> Wiggler | N12: {=IF(N$5="","",IFERROR(_xlfn.LET(_xlpm.x,_xlfn.SINGLE(INDEX(_xlfn._xlws.FILTER($E$6:$E$77,$D$6:$D$77=N$5),ROWS(N$6:N12))),IF(_xlpm.x=0,"",_xlpm.x)),""))} | O12: {=IF(O$5="","",IFERROR(_xlfn.LET(_xlpm.x,_xlfn.SINGLE(INDEX(_xlfn._xlws.FILTER($E$6:$E$77,$D$6:$D$77=O$5),ROWS(O$6:O12))),IF(_xlpm.x=0,"",_xlpm.x)),""))}
A13: =IF(ROW()-5<=$F$3,ROW()-5,"") -> 8 | B13: =IF($A13="","",ROUNDUP($A13/$D$3,0)) -> 2 | C13: =IF($A13="","",MOD($A13-1,$D$3)+1) -> 2 | D13: =IF($A13="","",IF(MOD($B13,2)=1,INDEX(Settings!$O$3:$O$10,$C13),INDEX(Settings!$O$3:$O$10,$D$3-$C13+1))) -> Jason | E13: Peach | H13: {=IF(H$5="","",IFERROR(_xlfn.LET(_xlpm.x,_xlfn.SINGLE(INDEX(_xlfn._xlws.FILTER($E$6:$E$77,$D$6:$D$77=H$5),ROWS(H$6:H13))),IF(_xlpm.x=0,"",_xlpm.x)),""))} -> Blue Kritter | I13: {=IF(I$5="","",IFERROR(_xlfn.LET(_xlpm.x,_xlfn.SINGLE(INDEX(_xlfn._xlws.FILTER($E$6:$E$77,$D$6:$D$77=I$5),ROWS(I$6:I13))),IF(_xlpm.x=0,"",_xlpm.x)),""))} -> Dry Bones | J13: {=IF(J$5="","",IFERROR(_xlfn.LET(_xlpm.x,_xlfn.SINGLE(INDEX(_xlfn._xlws.FILTER($E$6:$E$77,$D$6:$D$77=J$5),ROWS(J$6:J13))),IF(_xlpm.x=0,"",_xlpm.x)),""))} -> Blooper | K13: {=IF(K$5="","",IFERROR(_xlfn.LET(_xlpm.x,_xlfn.SINGLE(INDEX(_xlfn._xlws.FILTER($E$6:$E$77,$D$6:$D$77=K$5),ROWS(K$6:K13))),IF(_xlpm.x=0,"",_xlpm.x)),""))} -> Paratroopa | L13: {=IF(L$5="","",IFERROR(_xlfn.LET(_xlpm.x,_xlfn.SINGLE(INDEX(_xlfn._xlws.FILTER($E$6:$E$77,$D$6:$D$77=L$5),ROWS(L$6:L13))),IF(_xlpm.x=0,"",_xlpm.x)),""))} -> Green Shy Guy | M13: {=IF(M$5="","",IFERROR(_xlfn.LET(_xlpm.x,_xlfn.SINGLE(INDEX(_xlfn._xlws.FILTER($E$6:$E$77,$D$6:$D$77=M$5),ROWS(M$6:M13))),IF(_xlpm.x=0,"",_xlpm.x)),""))} -> Boomerang Bro | N13: {=IF(N$5="","",IFERROR(_xlfn.LET(_xlpm.x,_xlfn.SINGLE(INDEX(_xlfn._xlws.FILTER($E$6:$E$77,$D$6:$D$77=N$5),ROWS(N$6:N13))),IF(_xlpm.x=0,"",_xlpm.x)),""))} | O13: {=IF(O$5="","",IFERROR(_xlfn.LET(_xlpm.x,_xlfn.SINGLE(INDEX(_xlfn._xlws.FILTER($E$6:$E$77,$D$6:$D$77=O$5),ROWS(O$6:O13))),IF(_xlpm.x=0,"",_xlpm.x)),""))}
A14: =IF(ROW()-5<=$F$3,ROW()-5,"") -> 9 | B14: =IF($A14="","",ROUNDUP($A14/$D$3,0)) -> 2 | C14: =IF($A14="","",MOD($A14-1,$D$3)+1) -> 3 | D14: =IF($A14="","",IF(MOD($B14,2)=1,INDEX(Settings!$O$3:$O$10,$C14),INDEX(Settings!$O$3:$O$10,$D$3-$C14+1))) -> Aidan | E14: Luigi | H14: {=IF(H$5="","",IFERROR(_xlfn.LET(_xlpm.x,_xlfn.SINGLE(INDEX(_xlfn._xlws.FILTER($E$6:$E$77,$D$6:$D$77=H$5),ROWS(H$6:H14))),IF(_xlpm.x=0,"",_xlpm.x)),""))} -> Blue Dry Bones | I14: {=IF(I$5="","",IFERROR(_xlfn.LET(_xlpm.x,_xlfn.SINGLE(INDEX(_xlfn._xlws.FILTER($E$6:$E$77,$D$6:$D$77=I$5),ROWS(I$6:I14))),IF(_xlpm.x=0,"",_xlpm.x)),""))} -> Paragoomba | J14: {=IF(J$5="","",IFERROR(_xlfn.LET(_xlpm.x,_xlfn.SINGLE(INDEX(_xlfn._xlws.FILTER($E$6:$E$77,$D$6:$D$77=J$5),ROWS(J$6:J14))),IF(_xlpm.x=0,"",_xlpm.x)),""))} -> Yellow Toad | K14: {=IF(K$5="","",IFERROR(_xlfn.LET(_xlpm.x,_xlfn.SINGLE(INDEX(_xlfn._xlws.FILTER($E$6:$E$77,$D$6:$D$77=K$5),ROWS(K$6:K14))),IF(_xlpm.x=0,"",_xlpm.x)),""))} -> Kritter | L14: {=IF(L$5="","",IFERROR(_xlfn.LET(_xlpm.x,_xlfn.SINGLE(INDEX(_xlfn._xlws.FILTER($E$6:$E$77,$D$6:$D$77=L$5),ROWS(L$6:L14))),IF(_xlpm.x=0,"",_xlpm.x)),""))} -> Koopa | M14: {=IF(M$5="","",IFERROR(_xlfn.LET(_xlpm.x,_xlfn.SINGLE(INDEX(_xlfn._xlws.FILTER($E$6:$E$77,$D$6:$D$77=M$5),ROWS(M$6:M14))),IF(_xlpm.x=0,"",_xlpm.x)),""))} -> Green Dry Bones | N14: {=IF(N$5="","",IFERROR(_xlfn.LET(_xlpm.x,_xlfn.SINGLE(INDEX(_xlfn._xlws.FILTER($E$6:$E$77,$D$6:$D$77=N$5),ROWS(N$6:N14))),IF(_xlpm.x=0,"",_xlpm.x)),""))} | O14: {=IF(O$5="","",IFERROR(_xlfn.LET(_xlpm.x,_xlfn.SINGLE(INDEX(_xlfn._xlws.FILTER($E$6:$E$77,$D$6:$D$77=O$5),ROWS(O$6:O14))),IF(_xlpm.x=0,"",_xlpm.x)),""))}
A15: =IF(ROW()-5<=$F$3,ROW()-5,"") -> 10 | B15: =IF($A15="","",ROUNDUP($A15/$D$3,0)) -> 2 | C15: =IF($A15="","",MOD($A15-1,$D$3)+1) -> 4 | D15: =IF($A15="","",IF(MOD($B15,2)=1,INDEX(Settings!$O$3:$O$10,$C15),INDEX(Settings!$O$3:$O$10,$D$3-$C15+1))) -> Nick | E15: Mii
A16: =IF(ROW()-5<=$F$3,ROW()-5,"") -> 11 | B16: =IF($A16="","",ROUNDUP($A16/$D$3,0)) -> 2 | C16: =IF($A16="","",MOD($A16-1,$D$3)+1) -> 5 | D16: =IF($A16="","",IF(MOD($B16,2)=1,INDEX(Settings!$O$3:$O$10,$C16),INDEX(Settings!$O$3:$O$10,$D$3-$C16+1))) -> Donovan | E16: Waluigi
A17: =IF(ROW()-5<=$F$3,ROW()-5,"") -> 12 | B17: =IF($A17="","",ROUNDUP($A17/$D$3,0)) -> 2 | C17: =IF($A17="","",MOD($A17-1,$D$3)+1) -> 6 | D17: =IF($A17="","",IF(MOD($B17,2)=1,INDEX(Settings!$O$3:$O$10,$C17),INDEX(Settings!$O$3:$O$10,$D$3-$C17+1))) -> Justin | E17: Boo
A18: =IF(ROW()-5<=$F$3,ROW()-5,"") -> 13 | B18: =IF($A18="","",ROUNDUP($A18/$D$3,0)) -> 3 | C18: =IF($A18="","",MOD($A18-1,$D$3)+1) -> 1 | D18: =IF($A18="","",IF(MOD($B18,2)=1,INDEX(Settings!$O$3:$O$10,$C18),INDEX(Settings!$O$3:$O$10,$D$3-$C18+1))) -> Justin | E18: Funky Kong
A19: =IF(ROW()-5<=$F$3,ROW()-5,"") -> 14 | B19: =IF($A19="","",ROUNDUP($A19/$D$3,0)) -> 3 | C19: =IF($A19="","",MOD($A19-1,$D$3)+1) -> 2 | D19: =IF($A19="","",IF(MOD($B19,2)=1,INDEX(Settings!$O$3:$O$10,$C19),INDEX(Settings!$O$3:$O$10,$D$3-$C19+1))) -> Donovan | E19: Diddy Kong | K19: `
A20: =IF(ROW()-5<=$F$3,ROW()-5,"") -> 15 | B20: =IF($A20="","",ROUNDUP($A20/$D$3,0)) -> 3 | C20: =IF($A20="","",MOD($A20-1,$D$3)+1) -> 3 | D20: =IF($A20="","",IF(MOD($B20,2)=1,INDEX(Settings!$O$3:$O$10,$C20),INDEX(Settings!$O$3:$O$10,$D$3-$C20+1))) -> Nick | E20: Toadette
A21: =IF(ROW()-5<=$F$3,ROW()-5,"") -> 16 | B21: =IF($A21="","",ROUNDUP($A21/$D$3,0)) -> 3 | C21: =IF($A21="","",MOD($A21-1,$D$3)+1) -> 4 | D21: =IF($A21="","",IF(MOD($B21,2)=1,INDEX(Settings!$O$3:$O$10,$C21),INDEX(Settings!$O$3:$O$10,$D$3-$C21+1))) -> Aidan | E21: Dark Bones
A22: =IF(ROW()-5<=$F$3,ROW()-5,"") -> 17 | B22: =IF($A22="","",ROUNDUP($A22/$D$3,0)) -> 3 | C22: =IF($A22="","",MOD($A22-1,$D$3)+1) -> 5 | D22: =IF($A22="","",IF(MOD($B22,2)=1,INDEX(Settings!$O$3:$O$10,$C22),INDEX(Settings!$O$3:$O$10,$D$3-$C22+1))) -> Jason | E22: Yoshi
A23: =IF(ROW()-5<=$F$3,ROW()-5,"") -> 18 | B23: =IF($A23="","",ROUNDUP($A23/$D$3,0)) -> 3 | C23: =IF($A23="","",MOD($A23-1,$D$3)+1) -> 6 | D23: =IF($A23="","",IF(MOD($B23,2)=1,INDEX(Settings!$O$3:$O$10,$C23),INDEX(Settings!$O$3:$O$10,$D$3-$C23+1))) -> May | E23: King Boo
A24: =IF(ROW()-5<=$F$3,ROW()-5,"") -> 19 | B24: =IF($A24="","",ROUNDUP($A24/$D$3,0)) -> 4 | C24: =IF($A24="","",MOD($A24-1,$D$3)+1) -> 1 | D24: =IF($A24="","",IF(MOD($B24,2)=1,INDEX(Settings!$O$3:$O$10,$C24),INDEX(Settings!$O$3:$O$10,$D$3-$C24+1))) -> May | E24: Red Kritter
A25: =IF(ROW()-5<=$F$3,ROW()-5,"") -> 20 | B25: =IF($A25="","",ROUNDUP($A25/$D$3,0)) -> 4 | C25: =IF($A25="","",MOD($A25-1,$D$3)+1) -> 2 | D25: =IF($A25="","",IF(MOD($B25,2)=1,INDEX(Settings!$O$3:$O$10,$C25),INDEX(Settings!$O$3:$O$10,$D$3-$C25+1))) -> Jason | E25: King K. Rool
A26: =IF(ROW()-5<=$F$3,ROW()-5,"") -> 21 | B26: =IF($A26="","",ROUNDUP($A26/$D$3,0)) -> 4 | C26: =IF($A26="","",MOD($A26-1,$D$3)+1) -> 3 | D26: =IF($A26="","",IF(MOD($B26,2)=1,INDEX(Settings!$O$3:$O$10,$C26),INDEX(Settings!$O$3:$O$10,$D$3-$C26+1))) -> Aidan | E26: Pink Yoshi
A27: =IF(ROW()-5<=$F$3,ROW()-5,"") -> 22 | B27: =IF($A27="","",ROUNDUP($A27/$D$3,0)) -> 4 | C27: =IF($A27="","",MOD($A27-1,$D$3)+1) -> 4 | D27: =IF($A27="","",IF(MOD($B27,2)=1,INDEX(Settings!$O$3:$O$10,$C27),INDEX(Settings!$O$3:$O$10,$D$3-$C27+1))) -> Nick | E27: Blue Toad
A28: =IF(ROW()-5<=$F$3,ROW()-5,"") -> 23 | B28: =IF($A28="","",ROUNDUP($A28/$D$3,0)) -> 4 | C28: =IF($A28="","",MOD($A28-1,$D$3)+1) -> 5 | D28: =IF($A28="","",IF(MOD($B28,2)=1,INDEX(Settings!$O$3:$O$10,$C28),INDEX(Settings!$O$3:$O$10,$D$3-$C28+1))) -> Donovan | E28: Baby DK
A29: =IF(ROW()-5<=$F$3,ROW()-5,"") -> 24 | B29: =IF($A29="","",ROUNDUP($A29/$D$3,0)) -> 4 | C29: =IF($A29="","",MOD($A29-1,$D$3)+1) -> 6 | D29: =IF($A29="","",IF(MOD($B29,2)=1,INDEX(Settings!$O$3:$O$10,$C29),INDEX(Settings!$O$3:$O$10,$D$3-$C29+1))) -> Justin | E29: Yellow Magikoopa
A30: =IF(ROW()-5<=$F$3,ROW()-5,"") -> 25 | B30: =IF($A30="","",ROUNDUP($A30/$D$3,0)) -> 5 | C30: =IF($A30="","",MOD($A30-1,$D$3)+1) -> 1 | D30: =IF($A30="","",IF(MOD($B30,2)=1,INDEX(Settings!$O$3:$O$10,$C30),INDEX(Settings!$O$3:$O$10,$D$3-$C30+1))) -> Justin | E30: Blue Yoshi
A31: =IF(ROW()-5<=$F$3,ROW()-5,"") -> 26 | B31: =IF($A31="","",ROUNDUP($A31/$D$3,0)) -> 5 | C31: =IF($A31="","",MOD($A31-1,$D$3)+1) -> 2 | D31: =IF($A31="","",IF(MOD($B31,2)=1,INDEX(Settings!$O$3:$O$10,$C31),INDEX(Settings!$O$3:$O$10,$D$3-$C31+1))) -> Donovan | E31: Dixie Kong
... A59: =IF(ROW()-5<=$F$3,ROW()-5,"") -> 54 | B59: =IF($A59="","",ROUNDUP($A59/$D$3,0)) -> 9 | C59: =IF($A59="","",MOD($A59-1,$D$3)+1) -> 6 | D59: =IF($A59="","",IF(MOD($B59,2)=1,INDEX(Settings!$O$3:$O$10,$C59),INDEX(Settings!$O$3:$O$10,$D$3-$C59+1))) -> May | E59: Koopa
A60: =IF(ROW()-5<=$F$3,ROW()-5,"") | B60: =IF($A60="","",ROUNDUP($A60/$D$3,0)) | C60: =IF($A60="","",MOD($A60-1,$D$3)+1) | D60: =IF($A60="","",IF(MOD($B60,2)=1,INDEX(Settings!$O$3:$O$10,$C60),INDEX(Settings!$O$3:$O$10,$D$3-$C60+1)))
A61: =IF(ROW()-5<=$F$3,ROW()-5,"") | B61: =IF($A61="","",ROUNDUP($A61/$D$3,0)) | C61: =IF($A61="","",MOD($A61-1,$D$3)+1) | D61: =IF($A61="","",IF(MOD($B61,2)=1,INDEX(Settings!$O$3:$O$10,$C61),INDEX(Settings!$O$3:$O$10,$D$3-$C61+1)))
A62: =IF(ROW()-5<=$F$3,ROW()-5,"") | B62: =IF($A62="","",ROUNDUP($A62/$D$3,0)) | C62: =IF($A62="","",MOD($A62-1,$D$3)+1) | D62: =IF($A62="","",IF(MOD($B62,2)=1,INDEX(Settings!$O$3:$O$10,$C62),INDEX(Settings!$O$3:$O$10,$D$3-$C62+1)))
A63: =IF(ROW()-5<=$F$3,ROW()-5,"") | B63: =IF($A63="","",ROUNDUP($A63/$D$3,0)) | C63: =IF($A63="","",MOD($A63-1,$D$3)+1) | D63: =IF($A63="","",IF(MOD($B63,2)=1,INDEX(Settings!$O$3:$O$10,$C63),INDEX(Settings!$O$3:$O$10,$D$3-$C63+1)))
A64: =IF(ROW()-5<=$F$3,ROW()-5,"") | B64: =IF($A64="","",ROUNDUP($A64/$D$3,0)) | C64: =IF($A64="","",MOD($A64-1,$D$3)+1) | D64: =IF($A64="","",IF(MOD($B64,2)=1,INDEX(Settings!$O$3:$O$10,$C64),INDEX(Settings!$O$3:$O$10,$D$3-$C64+1)))
A65: =IF(ROW()-5<=$F$3,ROW()-5,"") | B65: =IF($A65="","",ROUNDUP($A65/$D$3,0)) | C65: =IF($A65="","",MOD($A65-1,$D$3)+1) | D65: =IF($A65="","",IF(MOD($B65,2)=1,INDEX(Settings!$O$3:$O$10,$C65),INDEX(Settings!$O$3:$O$10,$D$3-$C65+1)))
A66: =IF(ROW()-5<=$F$3,ROW()-5,"") | B66: =IF($A66="","",ROUNDUP($A66/$D$3,0)) | C66: =IF($A66="","",MOD($A66-1,$D$3)+1) | D66: =IF($A66="","",IF(MOD($B66,2)=1,INDEX(Settings!$O$3:$O$10,$C66),INDEX(Settings!$O$3:$O$10,$D$3-$C66+1)))
A67: =IF(ROW()-5<=$F$3,ROW()-5,"") | B67: =IF($A67="","",ROUNDUP($A67/$D$3,0)) | C67: =IF($A67="","",MOD($A67-1,$D$3)+1) | D67: =IF($A67="","",IF(MOD($B67,2)=1,INDEX(Settings!$O$3:$O$10,$C67),INDEX(Settings!$O$3:$O$10,$D$3-$C67+1)))
A68: =IF(ROW()-5<=$F$3,ROW()-5,"") | B68: =IF($A68="","",ROUNDUP($A68/$D$3,0)) | C68: =IF($A68="","",MOD($A68-1,$D$3)+1) | D68: =IF($A68="","",IF(MOD($B68,2)=1,INDEX(Settings!$O$3:$O$10,$C68),INDEX(Settings!$O$3:$O$10,$D$3-$C68+1)))
A69: =IF(ROW()-5<=$F$3,ROW()-5,"") | B69: =IF($A69="","",ROUNDUP($A69/$D$3,0)) | C69: =IF($A69="","",MOD($A69-1,$D$3)+1) | D69: =IF($A69="","",IF(MOD($B69,2)=1,INDEX(Settings!$O$3:$O$10,$C69),INDEX(Settings!$O$3:$O$10,$D$3-$C69+1)))
...

Sheet Lineups
A1: ="Game "&(QUOTIENT(ROW()-1,14)+1)&" Lineups" -> Game 1 Lineups
A2: Game ID | B2: {=INDEX(Bracket!$F$6:$F$20,QUOTIENT(ROW()-2,14)+1)} -> G1 | D2: Stage | E2: {=INDEX(Bracket!$G$6:$G$20,QUOTIENT(ROW()-2,14)+1)} -> Winners R1-1
A3: Team A Owner | B3: {=INDEX(Bracket!$H$6:$H$20,QUOTIENT(ROW()-3,14)+1)} -> Nick | F3: Team B Owner | G3: {=INDEX(Bracket!$I$6:$I$20,QUOTIENT(ROW()-3,14)+1)} -> Donovan
A4: Roster | B4: Batting Order | C4: Final | F4: Roster | G4: Batting Order | H4: Final
A5: {=_xlfn.LET(_xlpm.owner,INDEX($B:$B,3+14*QUOTIENT(ROW()-5,14)),_xlpm.slot,MOD(ROW()-5,14)+1,IF(_xlpm.owner="","",IFERROR(INDEX(Draft!$H$6:$N$14,_xlpm.slot,MATCH(_xlpm.owner,Draft!$H$5:$N$5,0)),"")))} -> Daisy | B5: 3 | C5: {=IF(A5="","",IFERROR(INDEX(_xlfn.SORTBY(OFFSET(A5,-MOD(ROW()-5,14),0,9,1),OFFSET(B5,-MOD(ROW()-5,14),0,9,1),1),MOD(ROW()-5,14)+1),""))} -> Monty Mole | F5: {=_xlfn.LET(_xlpm.owner,INDEX($G:$G,3+14*QUOTIENT(ROW()-5,14)),_xlpm.slot,MOD(ROW()-5,14)+1,IF(_xlpm.owner="","",IFERROR(INDEX(Draft!$H$6:$N$14,_xlpm.slot,MATCH(_xlpm.owner,Draft!$H$5:$N$5,0)),"")))} -> Donkey Kong | G5: 1 | H5: {=IF(F5="","",IFERROR(INDEX(_xlfn.SORTBY(OFFSET(F5,-MOD(ROW()-5,14),0,9,1),OFFSET(G5,-MOD(ROW()-5,14),0,9,1),1),MOD(ROW()-5,14)+1),""))} -> Donkey Kong
A6: {=_xlfn.LET(_xlpm.owner,INDEX($B:$B,3+14*QUOTIENT(ROW()-5,14)),_xlpm.slot,MOD(ROW()-5,14)+1,IF(_xlpm.owner="","",IFERROR(INDEX(Draft!$H$6:$N$14,_xlpm.slot,MATCH(_xlpm.owner,Draft!$H$5:$N$5,0)),"")))} -> Mii | B6: 6 | C6: {=IF(A6="","",IFERROR(INDEX(_xlfn.SORTBY(OFFSET(A6,-MOD(ROW()-5,14),0,9,1),OFFSET(B6,-MOD(ROW()-5,14),0,9,1),1),MOD(ROW()-5,14)+1),""))} -> Green Dry Bones | F6: {=_xlfn.LET(_xlpm.owner,INDEX($G:$G,3+14*QUOTIENT(ROW()-5,14)),_xlpm.slot,MOD(ROW()-5,14)+1,IF(_xlpm.owner="","",IFERROR(INDEX(Draft!$H$6:$N$14,_xlpm.slot,MATCH(_xlpm.owner,Draft!$H$5:$N$5,0)),"")))} -> Waluigi | G6: 2 | H6: {=IF(F6="","",IFERROR(INDEX(_xlfn.SORTBY(OFFSET(F6,-MOD(ROW()-5,14),0,9,1),OFFSET(G6,-MOD(ROW()-5,14),0,9,1),1),MOD(ROW()-5,14)+1),""))} -> Waluigi
A7: {=_xlfn.LET(_xlpm.owner,INDEX($B:$B,3+14*QUOTIENT(ROW()-5,14)),_xlpm.slot,MOD(ROW()-5,14)+1,IF(_xlpm.owner="","",IFERROR(INDEX(Draft!$H$6:$N$14,_xlpm.slot,MATCH(_xlpm.owner,Draft!$H$5:$N$5,0)),"")))} -> Toadette | B7: 8 | C7: {=IF(A7="","",IFERROR(INDEX(_xlfn.SORTBY(OFFSET(A7,-MOD(ROW()-5,14),0,9,1),OFFSET(B7,-MOD(ROW()-5,14),0,9,1),1),MOD(ROW()-5,14)+1),""))} -> Daisy | F7: {=_xlfn.LET(_xlpm.owner,INDEX($G:$G,3+14*QUOTIENT(ROW()-5,14)),_xlpm.slot,MOD(ROW()-5,14)+1,IF(_xlpm.owner="","",IFERROR(INDEX(Draft!$H$6:$N$14,_xlpm.slot,MATCH(_xlpm.owner,Draft!$H$5:$N$5,0)),"")))} -> Diddy Kong | G7: 4 | H7: {=IF(F7="","",IFERROR(INDEX(_xlfn.SORTBY(OFFSET(F7,-MOD(ROW()-5,14),0,9,1),OFFSET(G7,-MOD(ROW()-5,14),0,9,1),1),MOD(ROW()-5,14)+1),""))} -> Dry Bones
A8: {=_xlfn.LET(_xlpm.owner,INDEX($B:$B,3+14*QUOTIENT(ROW()-5,14)),_xlpm.slot,MOD(ROW()-5,14)+1,IF(_xlpm.owner="","",IFERROR(INDEX(Draft!$H$6:$N$14,_xlpm.slot,MATCH(_xlpm.owner,Draft!$H$5:$N$5,0)),"")))} -> Blue Toad | B8: 7 | C8: {=IF(A8="","",IFERROR(INDEX(_xlfn.SORTBY(OFFSET(A8,-MOD(ROW()-5,14),0,9,1),OFFSET(B8,-MOD(ROW()-5,14),0,9,1),1),MOD(ROW()-5,14)+1),""))} -> Wario | F8: {=_xlfn.LET(_xlpm.owner,INDEX($G:$G,3+14*QUOTIENT(ROW()-5,14)),_xlpm.slot,MOD(ROW()-5,14)+1,IF(_xlpm.owner="","",IFERROR(INDEX(Draft!$H$6:$N$14,_xlpm.slot,MATCH(_xlpm.owner,Draft!$H$5:$N$5,0)),"")))} -> Baby DK | G8: 7 | H8: {=IF(F8="","",IFERROR(INDEX(_xlfn.SORTBY(OFFSET(F8,-MOD(ROW()-5,14),0,9,1),OFFSET(G8,-MOD(ROW()-5,14),0,9,1),1),MOD(ROW()-5,14)+1),""))} -> Diddy Kong
A9: {=_xlfn.LET(_xlpm.owner,INDEX($B:$B,3+14*QUOTIENT(ROW()-5,14)),_xlpm.slot,MOD(ROW()-5,14)+1,IF(_xlpm.owner="","",IFERROR(INDEX(Draft!$H$6:$N$14,_xlpm.slot,MATCH(_xlpm.owner,Draft!$H$5:$N$5,0)),"")))} -> Monty Mole | B9: 1 | C9: {=IF(A9="","",IFERROR(INDEX(_xlfn.SORTBY(OFFSET(A9,-MOD(ROW()-5,14),0,9,1),OFFSET(B9,-MOD(ROW()-5,14),0,9,1),1),MOD(ROW()-5,14)+1),""))} -> Boomerang Bro | F9: {=_xlfn.LET(_xlpm.owner,INDEX($G:$G,3+14*QUOTIENT(ROW()-5,14)),_xlpm.slot,MOD(ROW()-5,14)+1,IF(_xlpm.owner="","",IFERROR(INDEX(Draft!$H$6:$N$14,_xlpm.slot,MATCH(_xlpm.owner,Draft!$H$5:$N$5,0)),"")))} -> Dixie Kong | G9: 6 | H9: {=IF(F9="","",IFERROR(INDEX(_xlfn.SORTBY(OFFSET(F9,-MOD(ROW()-5,14),0,9,1),OFFSET(G9,-MOD(ROW()-5,14),0,9,1),1),MOD(ROW()-5,14)+1),""))} -> Fire Bro
A10: {=_xlfn.LET(_xlpm.owner,INDEX($B:$B,3+14*QUOTIENT(ROW()-5,14)),_xlpm.slot,MOD(ROW()-5,14)+1,IF(_xlpm.owner="","",IFERROR(INDEX(Draft!$H$6:$N$14,_xlpm.slot,MATCH(_xlpm.owner,Draft!$H$5:$N$5,0)),"")))} -> Wario | B10: 4 | C10: {=IF(A10="","",IFERROR(INDEX(_xlfn.SORTBY(OFFSET(A10,-MOD(ROW()-5,14),0,9,1),OFFSET(B10,-MOD(ROW()-5,14),0,9,1),1),MOD(ROW()-5,14)+1),""))} -> Mii | F10: {=_xlfn.LET(_xlpm.owner,INDEX($G:$G,3+14*QUOTIENT(ROW()-5,14)),_xlpm.slot,MOD(ROW()-5,14)+1,IF(_xlpm.owner="","",IFERROR(INDEX(Draft!$H$6:$N$14,_xlpm.slot,MATCH(_xlpm.owner,Draft!$H$5:$N$5,0)),"")))} -> Fire Bro | G10: 5 | H10: {=IF(F10="","",IFERROR(INDEX(_xlfn.SORTBY(OFFSET(F10,-MOD(ROW()-5,14),0,9,1),OFFSET(G10,-MOD(ROW()-5,14),0,9,1),1),MOD(ROW()-5,14)+1),""))} -> Dixie Kong
A11: {=_xlfn.LET(_xlpm.owner,INDEX($B:$B,3+14*QUOTIENT(ROW()-5,14)),_xlpm.slot,MOD(ROW()-5,14)+1,IF(_xlpm.owner="","",IFERROR(INDEX(Draft!$H$6:$N$14,_xlpm.slot,MATCH(_xlpm.owner,Draft!$H$5:$N$5,0)),"")))} -> Wiggler | B11: 9 | C11: {=IF(A11="","",IFERROR(INDEX(_xlfn.SORTBY(OFFSET(A11,-MOD(ROW()-5,14),0,9,1),OFFSET(B11,-MOD(ROW()-5,14),0,9,1),1),MOD(ROW()-5,14)+1),""))} -> Blue Toad | F11: {=_xlfn.LET(_xlpm.owner,INDEX($G:$G,3+14*QUOTIENT(ROW()-5,14)),_xlpm.slot,MOD(ROW()-5,14)+1,IF(_xlpm.owner="","",IFERROR(INDEX(Draft!$H$6:$N$14,_xlpm.slot,MATCH(_xlpm.owner,Draft!$H$5:$N$5,0)),"")))} -> Tiny Kong | G11: 8 | H11: {=IF(F11="","",IFERROR(INDEX(_xlfn.SORTBY(OFFSET(F11,-MOD(ROW()-5,14),0,9,1),OFFSET(G11,-MOD(ROW()-5,14),0,9,1),1),MOD(ROW()-5,14)+1),""))} -> Baby DK
A12: {=_xlfn.LET(_xlpm.owner,INDEX($B:$B,3+14*QUOTIENT(ROW()-5,14)),_xlpm.slot,MOD(ROW()-5,14)+1,IF(_xlpm.owner="","",IFERROR(INDEX(Draft!$H$6:$N$14,_xlpm.slot,MATCH(_xlpm.owner,Draft!$H$5:$N$5,0)),"")))} -> Boomerang Bro | B12: 5 | C12: {=IF(A12="","",IFERROR(INDEX(_xlfn.SORTBY(OFFSET(A12,-MOD(ROW()-5,14),0,9,1),OFFSET(B12,-MOD(ROW()-5,14),0,9,1),1),MOD(ROW()-5,14)+1),""))} -> Toadette | F12: {=_xlfn.LET(_xlpm.owner,INDEX($G:$G,3+14*QUOTIENT(ROW()-5,14)),_xlpm.slot,MOD(ROW()-5,14)+1,IF(_xlpm.owner="","",IFERROR(INDEX(Draft!$H$6:$N$14,_xlpm.slot,MATCH(_xlpm.owner,Draft!$H$5:$N$5,0)),"")))} -> Dry Bones | G12: 3 | H12: {=IF(F12="","",IFERROR(INDEX(_xlfn.SORTBY(OFFSET(F12,-MOD(ROW()-5,14),0,9,1),OFFSET(G12,-MOD(ROW()-5,14),0,9,1),1),MOD(ROW()-5,14)+1),""))} -> Tiny Kong
A13: {=_xlfn.LET(_xlpm.owner,INDEX($B:$B,3+14*QUOTIENT(ROW()-5,14)),_xlpm.slot,MOD(ROW()-5,14)+1,IF(_xlpm.owner="","",IFERROR(INDEX(Draft!$H$6:$N$14,_xlpm.slot,MATCH(_xlpm.owner,Draft!$H$5:$N$5,0)),"")))} -> Green Dry Bones | B13: 2 | C13: {=IF(A13="","",IFERROR(INDEX(_xlfn.SORTBY(OFFSET(A13,-MOD(ROW()-5,14),0,9,1),OFFSET(B13,-MOD(ROW()-5,14),0,9,1),1),MOD(ROW()-5,14)+1),""))} -> Wiggler | F13: {=_xlfn.LET(_xlpm.owner,INDEX($G:$G,3+14*QUOTIENT(ROW()-5,14)),_xlpm.slot,MOD(ROW()-5,14)+1,IF(_xlpm.owner="","",IFERROR(INDEX(Draft!$H$6:$N$14,_xlpm.slot,MATCH(_xlpm.owner,Draft!$H$5:$N$5,0)),"")))} -> Paragoomba | G13: 9 | H13: {=IF(F13="","",IFERROR(INDEX(_xlfn.SORTBY(OFFSET(F13,-MOD(ROW()-5,14),0,9,1),OFFSET(G13,-MOD(ROW()-5,14),0,9,1),1),MOD(ROW()-5,14)+1),""))} -> Paragoomba
A15: ="Game "&(QUOTIENT(ROW()-1,14)+1)&" Lineups" -> Game 2 Lineups
A16: Game ID | B16: {=INDEX(Bracket!$F$6:$F$20,QUOTIENT(ROW()-2,14)+1)} -> G2 | D16: Stage | E16: {=INDEX(Bracket!$G$6:$G$20,QUOTIENT(ROW()-2,14)+1)} -> Winners R1-2
A17: Team A Owner | B17: {=INDEX(Bracket!$H$6:$H$20,QUOTIENT(ROW()-3,14)+1)} -> Aidan | F17: Team B Owner | G17: {=INDEX(Bracket!$I$6:$I$20,QUOTIENT(ROW()-3,14)+1)} -> Justin
A18: Roster | B18: Batting Order | C18: Final | F18: Roster | G18: Batting Order | H18: Final
A19: {=_xlfn.LET(_xlpm.owner,INDEX($B:$B,3+14*QUOTIENT(ROW()-5,14)),_xlpm.slot,MOD(ROW()-5,14)+1,IF(_xlpm.owner="","",IFERROR(INDEX(Draft!$H$6:$N$14,_xlpm.slot,MATCH(_xlpm.owner,Draft!$H$5:$N$5,0)),"")))} -> Mario | B19: 3 | C19: {=IF(A19="","",IFERROR(INDEX(_xlfn.SORTBY(OFFSET(A19,-MOD(ROW()-5,14),0,9,1),OFFSET(B19,-MOD(ROW()-5,14),0,9,1),1),MOD(ROW()-5,14)+1),""))} -> Dark Bones | F19: {=_xlfn.LET(_xlpm.owner,INDEX($G:$G,3+14*QUOTIENT(ROW()-5,14)),_xlpm.slot,MOD(ROW()-5,14)+1,IF(_xlpm.owner="","",IFERROR(INDEX(Draft!$H$6:$N$14,_xlpm.slot,MATCH(_xlpm.owner,Draft!$H$5:$N$5,0)),"")))} -> Bowser Jr. | G19: 1 | H19: {=IF(F19="","",IFERROR(INDEX(_xlfn.SORTBY(OFFSET(F19,-MOD(ROW()-5,14),0,9,1),OFFSET(G19,-MOD(ROW()-5,14),0,9,1),1),MOD(ROW()-5,14)+1),""))} -> Bowser Jr.
A20: {=_xlfn.LET(_xlpm.owner,INDEX($B:$B,3+14*QUOTIENT(ROW()-5,14)),_xlpm.slot,MOD(ROW()-5,14)+1,IF(_xlpm.owner="","",IFERROR(INDEX(Draft!$H$6:$N$14,_xlpm.slot,MATCH(_xlpm.owner,Draft!$H$5:$N$5,0)),"")))} -> Luigi | B20: 6 | C20: {=IF(A20="","",IFERROR(INDEX(_xlfn.SORTBY(OFFSET(A20,-MOD(ROW()-5,14),0,9,1),OFFSET(B20,-MOD(ROW()-5,14),0,9,1),1),MOD(ROW()-5,14)+1),""))} -> Blue Pianta | F20: {=_xlfn.LET(_xlpm.owner,INDEX($G:$G,3+14*QUOTIENT(ROW()-5,14)),_xlpm.slot,MOD(ROW()-5,14)+1,IF(_xlpm.owner="","",IFERROR(INDEX(Draft!$H$6:$N$14,_xlpm.slot,MATCH(_xlpm.owner,Draft!$H$5:$N$5,0)),"")))} -> Boo | G20: 9 | H20: {=IF(F20="","",IFERROR(INDEX(_xlfn.SORTBY(OFFSET(F20,-MOD(ROW()-5,14),0,9,1),OFFSET(G20,-MOD(ROW()-5,14),0,9,1),1),MOD(ROW()-5,14)+1),""))} -> Kritter
A21: {=_xlfn.LET(_xlpm.owner,INDEX($B:$B,3+14*QUOTIENT(ROW()-5,14)),_xlpm.slot,MOD(ROW()-5,14)+1,IF(_xlpm.owner="","",IFERROR(INDEX(Draft!$H$6:$N$14,_xlpm.slot,MATCH(_xlpm.owner,Draft!$H$5:$N$5,0)),"")))} -> Dark Bones | B21: 1 | C21: {=IF(A21="","",IFERROR(INDEX(_xlfn.SORTBY(OFFSET(A21,-MOD(ROW()-5,14),0,9,1),OFFSET(B21,-MOD(ROW()-5,14),0,9,1),1),MOD(ROW()-5,14)+1),""))} -> Mario | F21: {=_xlfn.LET(_xlpm.owner,INDEX($G:$G,3+14*QUOTIENT(ROW()-5,14)),_xlpm.slot,MOD(ROW()-5,14)+1,IF(_xlpm.owner="","",IFERROR(INDEX(Draft!$H$6:$N$14,_xlpm.slot,MATCH(_xlpm.owner,Draft!$H$5:$N$5,0)),"")))} -> Funky Kong | G21: 3 | H21: {=IF(F21="","",IFERROR(INDEX(_xlfn.SORTBY(OFFSET(F21,-MOD(ROW()-5,14),0,9,1),OFFSET(G21,-MOD(ROW()-5,14),0,9,1),1),MOD(ROW()-5,14)+1),""))} -> Funky Kong
A22: {=_xlfn.LET(_xlpm.owner,INDEX($B:$B,3+14*QUOTIENT(ROW()-5,14)),_xlpm.slot,MOD(ROW()-5,14)+1,IF(_xlpm.owner="","",IFERROR(INDEX(Draft!$H$6:$N$14,_xlpm.slot,MATCH(_xlpm.owner,Draft!$H$5:$N$5,0)),"")))} -> Pink Yoshi | B22: 9 | C22: {=IF(A22="","",IFERROR(INDEX(_xlfn.SORTBY(OFFSET(A22,-MOD(ROW()-5,14),0,9,1),OFFSET(B22,-MOD(ROW()-5,14),0,9,1),1),MOD(ROW()-5,14)+1),""))} -> Yellow Pianta | F22: {=_xlfn.LET(_xlpm.owner,INDEX($G:$G,3+14*QUOTIENT(ROW()-5,14)),_xlpm.slot,MOD(ROW()-5,14)+1,IF(_xlpm.owner="","",IFERROR(INDEX(Draft!$H$6:$N$14,_xlpm.slot,MATCH(_xlpm.owner,Draft!$H$5:$N$5,0)),"")))} -> Yellow Magikoopa | G22: 8 | H22: {=IF(F22="","",IFERROR(INDEX(_xlfn.SORTBY(OFFSET(F22,-MOD(ROW()-5,14),0,9,1),OFFSET(G22,-MOD(ROW()-5,14),0,9,1),1),MOD(ROW()-5,14)+1),""))} -> Red Pianta
A23: {=_xlfn.LET(_xlpm.owner,INDEX($B:$B,3+14*QUOTIENT(ROW()-5,14)),_xlpm.slot,MOD(ROW()-5,14)+1,IF(_xlpm.owner="","",IFERROR(INDEX(Draft!$H$6:$N$14,_xlpm.slot,MATCH(_xlpm.owner,Draft!$H$5:$N$5,0)),"")))} -> Red Magikoopa | B23: 8 | C23: {=IF(A23="","",IFERROR(INDEX(_xlfn.SORTBY(OFFSET(A23,-MOD(ROW()-5,14),0,9,1),OFFSET(B23,-MOD(ROW()-5,14),0,9,1),1),MOD(ROW()-5,14)+1),""))} -> Blue Kritter | F23: {=_xlfn.LET(_xlpm.owner,INDEX($G:$G,3+14*QUOTIENT(ROW()-5,14)),_xlpm.slot,MOD(ROW()-5,14)+1,IF(_xlpm.owner="","",IFERROR(INDEX(Draft!$H$6:$N$14,_xlpm.slot,MATCH(_xlpm.owner,Draft!$H$5:$N$5,0)),"")))} -> Blue Yoshi | G23: 5 | H23: {=IF(F23="","",IFERROR(INDEX(_xlfn.SORTBY(OFFSET(F23,-MOD(ROW()-5,14),0,9,1),OFFSET(G23,-MOD(ROW()-5,14),0,9,1),1),MOD(ROW()-5,14)+1),""))} -> Blue Yoshi
A24: {=_xlfn.LET(_xlpm.owner,INDEX($B:$B,3+14*QUOTIENT(ROW()-5,14)),_xlpm.slot,MOD(ROW()-5,14)+1,IF(_xlpm.owner="","",IFERROR(INDEX(Draft!$H$6:$N$14,_xlpm.slot,MATCH(_xlpm.owner,Draft!$H$5:$N$5,0)),"")))} -> Blue Pianta | B24: 2 | C24: {=IF(A24="","",IFERROR(INDEX(_xlfn.SORTBY(OFFSET(A24,-MOD(ROW()-5,14),0,9,1),OFFSET(B24,-MOD(ROW()-5,14),0,9,1),1),MOD(ROW()-5,14)+1),""))} -> Luigi | F24: {=_xlfn.LET(_xlpm.owner,INDEX($G:$G,3+14*QUOTIENT(ROW()-5,14)),_xlpm.slot,MOD(ROW()-5,14)+1,IF(_xlpm.owner="","",IFERROR(INDEX(Draft!$H$6:$N$14,_xlpm.slot,MATCH(_xlpm.owner,Draft!$H$5:$N$5,0)),"")))} -> Red Pianta | G24: 4 | H24: {=IF(F24="","",IFERROR(INDEX(_xlfn.SORTBY(OFFSET(F24,-MOD(ROW()-5,14),0,9,1),OFFSET(G24,-MOD(ROW()-5,14),0,9,1),1),MOD(ROW()-5,14)+1),""))} -> Baby Luigi
A25: {=_xlfn.LET(_xlpm.owner,INDEX($B:$B,3+14*QUOTIENT(ROW()-5,14)),_xlpm.slot,MOD(ROW()-5,14)+1,IF(_xlpm.owner="","",IFERROR(INDEX(Draft!$H$6:$N$14,_xlpm.slot,MATCH(_xlpm.owner,Draft!$H$5:$N$5,0)),"")))} -> Yellow Pianta | B25: 4 | C25: {=IF(A25="","",IFERROR(INDEX(_xlfn.SORTBY(OFFSET(A25,-MOD(ROW()-5,14),0,9,1),OFFSET(B25,-MOD(ROW()-5,14),0,9,1),1),MOD(ROW()-5,14)+1),""))} -> Blue Dry Bones | F25: {=_xlfn.LET(_xlpm.owner,INDEX($G:$G,3+14*QUOTIENT(ROW()-5,14)),_xlpm.slot,MOD(ROW()-5,14)+1,IF(_xlpm.owner="","",IFERROR(INDEX(Draft!$H$6:$N$14,_xlpm.slot,MATCH(_xlpm.owner,Draft!$H$5:$N$5,0)),"")))} -> Baby Luigi | G25: 6 | H25: {=IF(F25="","",IFERROR(INDEX(_xlfn.SORTBY(OFFSET(F25,-MOD(ROW()-5,14),0,9,1),OFFSET(G25,-MOD(ROW()-5,14),0,9,1),1),MOD(ROW()-5,14)+1),""))} -> Paratroopa
A26: {=_xlfn.LET(_xlpm.owner,INDEX($B:$B,3+14*QUOTIENT(ROW()-5,14)),_xlpm.slot,MOD(ROW()-5,14)+1,IF(_xlpm.owner="","",IFERROR(INDEX(Draft!$H$6:$N$14,_xlpm.slot,MATCH(_xlpm.owner,Draft!$H$5:$N$5,0)),"")))} -> Blue Kritter | B26: 5 | C26: {=IF(A26="","",IFERROR(INDEX(_xlfn.SORTBY(OFFSET(A26,-MOD(ROW()-5,14),0,9,1),OFFSET(B26,-MOD(ROW()-5,14),0,9,1),1),MOD(ROW()-5,14)+1),""))} -> Red Magikoopa | F26: {=_xlfn.LET(_xlpm.owner,INDEX($G:$G,3+14*QUOTIENT(ROW()-5,14)),_xlpm.slot,MOD(ROW()-5,14)+1,IF(_xlpm.owner="","",IFERROR(INDEX(Draft!$H$6:$N$14,_xlpm.slot,MATCH(_xlpm.owner,Draft!$H$5:$N$5,0)),"")))} -> Paratroopa | G26: 7 | H26: {=IF(F26="","",IFERROR(INDEX(_xlfn.SORTBY(OFFSET(F26,-MOD(ROW()-5,14),0,9,1),OFFSET(G26,-MOD(ROW()-5,14),0,9,1),1),MOD(ROW()-5,14)+1),""))} -> Yellow Magikoopa
A27: {=_xlfn.LET(_xlpm.owner,INDEX($B:$B,3+14*QUOTIENT(ROW()-5,14)),_xlpm.slot,MOD(ROW()-5,14)+1,IF(_xlpm.owner="","",IFERROR(INDEX(Draft!$H$6:$N$14,_xlpm.slot,MATCH(_xlpm.owner,Draft!$H$5:$N$5,0)),"")))} -> Blue Dry Bones | B27: 7 | C27: {=IF(A27="","",IFERROR(INDEX(_xlfn.SORTBY(OFFSET(A27,-MOD(ROW()-5,14),0,9,1),OFFSET(B27,-MOD(ROW()-5,14),0,9,1),1),MOD(ROW()-5,14)+1),""))} -> Pink Yoshi | F27: {=_xlfn.LET(_xlpm.owner,INDEX($G:$G,3+14*QUOTIENT(ROW()-5,14)),_xlpm.slot,MOD(ROW()-5,14)+1,IF(_xlpm.owner="","",IFERROR(INDEX(Draft!$H$6:$N$14,_xlpm.slot,MATCH(_xlpm.owner,Draft!$H$5:$N$5,0)),"")))} -> Kritter | G27: 2 | H27: {=IF(F27="","",IFERROR(INDEX(_xlfn.SORTBY(OFFSET(F27,-MOD(ROW()-5,14),0,9,1),OFFSET(G27,-MOD(ROW()-5,14),0,9,1),1),MOD(ROW()-5,14)+1),""))} -> Boo
A29: ="Game "&(QUOTIENT(ROW()-1,14)+1)&" Lineups" -> Game 3 Lineups
A30: Game ID | B30: {=INDEX(Bracket!$F$6:$F$20,QUOTIENT(ROW()-2,14)+1)} -> G3 | D30: Stage | E30: {=INDEX(Bracket!$G$6:$G$20,QUOTIENT(ROW()-2,14)+1)} -> Winners R2-1
A31: Team A Owner | B31: {=INDEX(Bracket!$H$6:$H$20,QUOTIENT(ROW()-3,14)+1)} -> May | F31: Team B Owner | G31: {=INDEX(Bracket!$I$6:$I$20,QUOTIENT(ROW()-3,14)+1)} -> Nick
A32: Roster | B32: Batting Order | C32: Final | F32: Roster | G32: Batting Order | H32: Final
A33: {=_xlfn.LET(_xlpm.owner,INDEX($B:$B,3+14*QUOTIENT(ROW()-5,14)),_xlpm.slot,MOD(ROW()-5,14)+1,IF(_xlpm.owner="","",IFERROR(INDEX(Draft!$H$6:$N$14,_xlpm.slot,MATCH(_xlpm.owner,Draft!$H$5:$N$5,0)),"")))} -> Birdo | B33: 1 | C33: {=IF(A33="","",IFERROR(INDEX(_xlfn.SORTBY(OFFSET(A33,-MOD(ROW()-5,14),0,9,1),OFFSET(B33,-MOD(ROW()-5,14),0,9,1),1),MOD(ROW()-5,14)+1),""))} -> Birdo | F33: {=_xlfn.LET(_xlpm.owner,INDEX($G:$G,3+14*QUOTIENT(ROW()-5,14)),_xlpm.slot,MOD(ROW()-5,14)+1,IF(_xlpm.owner="","",IFERROR(INDEX(Draft!$H$6:$N$14,_xlpm.slot,MATCH(_xlpm.owner,Draft!$H$5:$N$5,0)),"")))} -> Daisy | G33: 7 | H33: {=IF(F33="","",IFERROR(INDEX(_xlfn.SORTBY(OFFSET(F33,-MOD(ROW()-5,14),0,9,1),OFFSET(G33,-MOD(ROW()-5,14),0,9,1),1),MOD(ROW()-5,14)+1),""))} -> Monty Mole
A34: {=_xlfn.LET(_xlpm.owner,INDEX($B:$B,3+14*QUOTIENT(ROW()-5,14)),_xlpm.slot,MOD(ROW()-5,14)+1,IF(_xlpm.owner="","",IFERROR(INDEX(Draft!$H$6:$N$14,_xlpm.slot,MATCH(_xlpm.owner,Draft!$H$5:$N$5,0)),"")))} -> Petey Piranha | B34: 2 | C34: {=IF(A34="","",IFERROR(INDEX(_xlfn.SORTBY(OFFSET(A34,-MOD(ROW()-5,14),0,9,1),OFFSET(B34,-MOD(ROW()-5,14),0,9,1),1),MOD(ROW()-5,14)+1),""))} -> Petey Piranha | F34: {=_xlfn.LET(_xlpm.owner,INDEX($G:$G,3+14*QUOTIENT(ROW()-5,14)),_xlpm.slot,MOD(ROW()-5,14)+1,IF(_xlpm.owner="","",IFERROR(INDEX(Draft!$H$6:$N$14,_xlpm.slot,MATCH(_xlpm.owner,Draft!$H$5:$N$5,0)),"")))} -> Mii | G34: 4 | H34: {=IF(F34="","",IFERROR(INDEX(_xlfn.SORTBY(OFFSET(F34,-MOD(ROW()-5,14),0,9,1),OFFSET(G34,-MOD(ROW()-5,14),0,9,1),1),MOD(ROW()-5,14)+1),""))} -> Boomerang Bro
A35: {=_xlfn.LET(_xlpm.owner,INDEX($B:$B,3+14*QUOTIENT(ROW()-5,14)),_xlpm.slot,MOD(ROW()-5,14)+1,IF(_xlpm.owner="","",IFERROR(INDEX(Draft!$H$6:$N$14,_xlpm.slot,MATCH(_xlpm.owner,Draft!$H$5:$N$5,0)),"")))} -> King Boo | B35: 3 | C35: {=IF(A35="","",IFERROR(INDEX(_xlfn.SORTBY(OFFSET(A35,-MOD(ROW()-5,14),0,9,1),OFFSET(B35,-MOD(ROW()-5,14),0,9,1),1),MOD(ROW()-5,14)+1),""))} -> King Boo | F35: {=_xlfn.LET(_xlpm.owner,INDEX($G:$G,3+14*QUOTIENT(ROW()-5,14)),_xlpm.slot,MOD(ROW()-5,14)+1,IF(_xlpm.owner="","",IFERROR(INDEX(Draft!$H$6:$N$14,_xlpm.slot,MATCH(_xlpm.owner,Draft!$H$5:$N$5,0)),"")))} -> Toadette | G35: 6 | H35: {=IF(F35="","",IFERROR(INDEX(_xlfn.SORTBY(OFFSET(F35,-MOD(ROW()-5,14),0,9,1),OFFSET(G35,-MOD(ROW()-5,14),0,9,1),1),MOD(ROW()-5,14)+1),""))} -> Wiggler
A36: {=_xlfn.LET(_xlpm.owner,INDEX($B:$B,3+14*QUOTIENT(ROW()-5,14)),_xlpm.slot,MOD(ROW()-5,14)+1,IF(_xlpm.owner="","",IFERROR(INDEX(Draft!$H$6:$N$14,_xlpm.slot,MATCH(_xlpm.owner,Draft!$H$5:$N$5,0)),"")))} -> Red Kritter | B36: 4 | C36: {=IF(A36="","",IFERROR(INDEX(_xlfn.SORTBY(OFFSET(A36,-MOD(ROW()-5,14),0,9,1),OFFSET(B36,-MOD(ROW()-5,14),0,9,1),1),MOD(ROW()-5,14)+1),""))} -> Red Kritter | F36: {=_xlfn.LET(_xlpm.owner,INDEX($G:$G,3+14*QUOTIENT(ROW()-5,14)),_xlpm.slot,MOD(ROW()-5,14)+1,IF(_xlpm.owner="","",IFERROR(INDEX(Draft!$H$6:$N$14,_xlpm.slot,MATCH(_xlpm.owner,Draft!$H$5:$N$5,0)),"")))} -> Blue Toad | G36: 8 | H36: {=IF(F36="","",IFERROR(INDEX(_xlfn.SORTBY(OFFSET(F36,-MOD(ROW()-5,14),0,9,1),OFFSET(G36,-MOD(ROW()-5,14),0,9,1),1),MOD(ROW()-5,14)+1),""))} -> Mii
A37: {=_xlfn.LET(_xlpm.owner,INDEX($B:$B,3+14*QUOTIENT(ROW()-5,14)),_xlpm.slot,MOD(ROW()-5,14)+1,IF(_xlpm.owner="","",IFERROR(INDEX(Draft!$H$6:$N$14,_xlpm.slot,MATCH(_xlpm.owner,Draft!$H$5:$N$5,0)),"")))} -> Red Yoshi | B37: 8 | C37: {=IF(A37="","",IFERROR(INDEX(_xlfn.SORTBY(OFFSET(A37,-MOD(ROW()-5,14),0,9,1),OFFSET(B37,-MOD(ROW()-5,14),0,9,1),1),MOD(ROW()-5,14)+1),""))} -> Hammer Bro | F37: {=_xlfn.LET(_xlpm.owner,INDEX($G:$G,3+14*QUOTIENT(ROW()-5,14)),_xlpm.slot,MOD(ROW()-5,14)+1,IF(_xlpm.owner="","",IFERROR(INDEX(Draft!$H$6:$N$14,_xlpm.slot,MATCH(_xlpm.owner,Draft!$H$5:$N$5,0)),"")))} -> Monty Mole | G37: 1 | H37: {=IF(F37="","",IFERROR(INDEX(_xlfn.SORTBY(OFFSET(F37,-MOD(ROW()-5,14),0,9,1),OFFSET(G37,-MOD(ROW()-5,14),0,9,1),1),MOD(ROW()-5,14)+1),""))} -> Green Dry Bones
A38: {=_xlfn.LET(_xlpm.owner,INDEX($B:$B,3+14*QUOTIENT(ROW()-5,14)),_xlpm.slot,MOD(ROW()-5,14)+1,IF(_xlpm.owner="","",IFERROR(INDEX(Draft!$H$6:$N$14,_xlpm.slot,MATCH(_xlpm.owner,Draft!$H$5:$N$5,0)),"")))} -> Baby Peach | B38: 9 | C38: {=IF(A38="","",IFERROR(INDEX(_xlfn.SORTBY(OFFSET(A38,-MOD(ROW()-5,14),0,9,1),OFFSET(B38,-MOD(ROW()-5,14),0,9,1),1),MOD(ROW()-5,14)+1),""))} -> Koopa | F38: {=_xlfn.LET(_xlpm.owner,INDEX($G:$G,3+14*QUOTIENT(ROW()-5,14)),_xlpm.slot,MOD(ROW()-5,14)+1,IF(_xlpm.owner="","",IFERROR(INDEX(Draft!$H$6:$N$14,_xlpm.slot,MATCH(_xlpm.owner,Draft!$H$5:$N$5,0)),"")))} -> Wario | G38: 9 | H38: {=IF(F38="","",IFERROR(INDEX(_xlfn.SORTBY(OFFSET(F38,-MOD(ROW()-5,14),0,9,1),OFFSET(G38,-MOD(ROW()-5,14),0,9,1),1),MOD(ROW()-5,14)+1),""))} -> Toadette
A39: {=_xlfn.LET(_xlpm.owner,INDEX($B:$B,3+14*QUOTIENT(ROW()-5,14)),_xlpm.slot,MOD(ROW()-5,14)+1,IF(_xlpm.owner="","",IFERROR(INDEX(Draft!$H$6:$N$14,_xlpm.slot,MATCH(_xlpm.owner,Draft!$H$5:$N$5,0)),"")))} -> Hammer Bro | B39: 5 | C39: {=IF(A39="","",IFERROR(INDEX(_xlfn.SORTBY(OFFSET(A39,-MOD(ROW()-5,14),0,9,1),OFFSET(B39,-MOD(ROW()-5,14),0,9,1),1),MOD(ROW()-5,14)+1),""))} -> Green Shy Guy | F39: {=_xlfn.LET(_xlpm.owner,INDEX($G:$G,3+14*QUOTIENT(ROW()-5,14)),_xlpm.slot,MOD(ROW()-5,14)+1,IF(_xlpm.owner="","",IFERROR(INDEX(Draft!$H$6:$N$14,_xlpm.slot,MATCH(_xlpm.owner,Draft!$H$5:$N$5,0)),"")))} -> Wiggler | G39: 3 | H39: {=IF(F39="","",IFERROR(INDEX(_xlfn.SORTBY(OFFSET(F39,-MOD(ROW()-5,14),0,9,1),OFFSET(G39,-MOD(ROW()-5,14),0,9,1),1),MOD(ROW()-5,14)+1),""))} -> Daisy
A40: {=_xlfn.LET(_xlpm.owner,INDEX($B:$B,3+14*QUOTIENT(ROW()-5,14)),_xlpm.slot,MOD(ROW()-5,14)+1,IF(_xlpm.owner="","",IFERROR(INDEX(Draft!$H$6:$N$14,_xlpm.slot,MATCH(_xlpm.owner,Draft!$H$5:$N$5,0)),"")))} -> Green Shy Guy | B40: 7 | C40: {=IF(A40="","",IFERROR(INDEX(_xlfn.SORTBY(OFFSET(A40,-MOD(ROW()-5,14),0,9,1),OFFSET(B40,-MOD(ROW()-5,14),0,9,1),1),MOD(ROW()-5,14)+1),""))} -> Red Yoshi | F40: {=_xlfn.LET(_xlpm.owner,INDEX($G:$G,3+14*QUOTIENT(ROW()-5,14)),_xlpm.slot,MOD(ROW()-5,14)+1,IF(_xlpm.owner="","",IFERROR(INDEX(Draft!$H$6:$N$14,_xlpm.slot,MATCH(_xlpm.owner,Draft!$H$5:$N$5,0)),"")))} -> Boomerang Bro | G40: 2 | H40: {=IF(F40="","",IFERROR(INDEX(_xlfn.SORTBY(OFFSET(F40,-MOD(ROW()-5,14),0,9,1),OFFSET(G40,-MOD(ROW()-5,14),0,9,1),1),MOD(ROW()-5,14)+1),""))} -> Blue Toad
A41: {=_xlfn.LET(_xlpm.owner,INDEX($B:$B,3+14*QUOTIENT(ROW()-5,14)),_xlpm.slot,MOD(ROW()-5,14)+1,IF(_xlpm.owner="","",IFERROR(INDEX(Draft!$H$6:$N$14,_xlpm.slot,MATCH(_xlpm.owner,Draft!$H$5:$N$5,0)),"")))} -> Koopa | B41: 6 | C41: {=IF(A41="","",IFERROR(INDEX(_xlfn.SORTBY(OFFSET(A41,-MOD(ROW()-5,14),0,9,1),OFFSET(B41,-MOD(ROW()-5,14),0,9,1),1),MOD(ROW()-5,14)+1),""))} -> Baby Peach | F41: {=_xlfn.LET(_xlpm.owner,INDEX($G:$G,3+14*QUOTIENT(ROW()-5,14)),_xlpm.slot,MOD(ROW()-5,14)+1,IF(_xlpm.owner="","",IFERROR(INDEX(Draft!$H$6:$N$14,_xlpm.slot,MATCH(_xlpm.owner,Draft!$H$5:$N$5,0)),"")))} -> Green Dry Bones | G41: 5 | H41: {=IF(F41="","",IFERROR(INDEX(_xlfn.SORTBY(OFFSET(F41,-MOD(ROW()-5,14),0,9,1),OFFSET(G41,-MOD(ROW()-5,14),0,9,1),1),MOD(ROW()-5,14)+1),""))} -> Wario
A43: ="Game "&(QUOTIENT(ROW()-1,14)+1)&" Lineups" -> Game 4 Lineups
...

Sheet Character List
A1: Character Reference
A3: # | B3: Character | C3: Pitching | D3: Batting | E3: Fielding | F3: Speed | G3: Drafted? | H3: Current Owner
A4: 17 | B4: Bowser | C4: 5 | D4: 10 | E4: 3 | F4: 3 | G4: =IF(COUNTIF(Data!$D$4:$D$75,B4)>0,"Drafted","Available") -> Drafted | H4: =IFERROR(INDEX(Data!$C$4:$C$75,MATCH(B4,Data!$D$4:$D$75,0)),"") -> Jason
A5: 24 | B5: Petey Piranha | C5: 4 | D5: 10 | E5: 5 | F5: 2 | G5: =IF(COUNTIF(Data!$D$4:$D$75,B5)>0,"Drafted","Available") -> Drafted | H5: =IFERROR(INDEX(Data!$C$4:$C$75,MATCH(B5,Data!$D$4:$D$75,0)),"") -> May
A6: 67 | B6: King K. Rool | C6: 6 | D6: 10 | E6: 2 | F6: 1 | G6: =IF(COUNTIF(Data!$D$4:$D$75,B6)>0,"Drafted","Available") -> Drafted | H6: =IFERROR(INDEX(Data!$C$4:$C$75,MATCH(B6,Data!$D$4:$D$75,0)),"") -> Jason
A7: 36 | B7: Donkey Kong | C7: 6 | D7: 9 | E7: 3 | F7: 2 | G7: =IF(COUNTIF(Data!$D$4:$D$75,B7)>0,"Drafted","Available") -> Drafted | H7: =IFERROR(INDEX(Data!$C$4:$C$75,MATCH(B7,Data!$D$4:$D$75,0)),"") -> Donovan
A8: 6 | B8: Birdo | C8: 4 | D8: 8 | E8: 7 | F8: 5 | G8: =IF(COUNTIF(Data!$D$4:$D$75,B8)>0,"Drafted","Available") -> Drafted | H8: =IFERROR(INDEX(Data!$C$4:$C$75,MATCH(B8,Data!$D$4:$D$75,0)),"") -> May
A9: 20 | B9: Funky Kong | C9: 4 | D9: 8 | E9: 6 | F9: 3 | G9: =IF(COUNTIF(Data!$D$4:$D$75,B9)>0,"Drafted","Available") -> Drafted | H9: =IFERROR(INDEX(Data!$C$4:$C$75,MATCH(B9,Data!$D$4:$D$75,0)),"") -> Justin
A10: 25 | B10: Red Kritter | C10: 3 | D10: 8 | E10: 7 | F10: 3 | G10: =IF(COUNTIF(Data!$D$4:$D$75,B10)>0,"Drafted","Available") -> Drafted | H10: =IFERROR(INDEX(Data!$C$4:$C$75,MATCH(B10,Data!$D$4:$D$75,0)),"") -> May
A11: 38 | B11: Fire Bro | C11: 3 | D11: 8 | E11: 6 | F11: 3 | G11: =IF(COUNTIF(Data!$D$4:$D$75,B11)>0,"Drafted","Available") -> Drafted | H11: =IFERROR(INDEX(Data!$C$4:$C$75,MATCH(B11,Data!$D$4:$D$75,0)),"") -> Donovan
A12: 58 | B12: Wario | C12: 5 | D12: 8 | E12: 3 | F12: 4 | G12: =IF(COUNTIF(Data!$D$4:$D$75,B12)>0,"Drafted","Available") -> Drafted | H12: =IFERROR(INDEX(Data!$C$4:$C$75,MATCH(B12,Data!$D$4:$D$75,0)),"") -> Nick
A13: 63 | B13: Blue Pianta | C13: 5 | D13: 8 | E13: 4 | F13: 2 | G13: =IF(COUNTIF(Data!$D$4:$D$75,B13)>0,"Drafted","Available") -> Drafted | H13: =IFERROR(INDEX(Data!$C$4:$C$75,MATCH(B13,Data!$D$4:$D$75,0)),"") -> Aidan
A14: 71 | B14: Red Pianta | C14: 4 | D14: 8 | E14: 4 | F14: 2 | G14: =IF(COUNTIF(Data!$D$4:$D$75,B14)>0,"Drafted","Available") -> Drafted | H14: =IFERROR(INDEX(Data!$C$4:$C$75,MATCH(B14,Data!$D$4:$D$75,0)),"") -> Justin
A15: 72 | B15: Yellow Pianta | C15: 4 | D15: 8 | E15: 4 | F15: 2 | G15: =IF(COUNTIF(Data!$D$4:$D$75,B15)>0,"Drafted","Available") -> Drafted | H15: =IFERROR(INDEX(Data!$C$4:$C$75,MATCH(B15,Data!$D$4:$D$75,0)),"") -> Aidan
... A75: 66 | B75: Green Magikoopa | C75: 7 | D75: 2 | E75: 8 | F75: 2 | G75: =IF(COUNTIF(Data!$D$4:$D$75,B75)>0,"Drafted","Available") -> Available | H75: =IFERROR(INDEX(Data!$C$4:$C$75,MATCH(B75,Data!$D$4:$D$75,0)),"")

Sheet Bracket
A1: Current Tournament Bracket
A3: Tournament | B3: =Settings!$B$2 -> 1 | F3: Player Count | G3: =Settings!$B$3 -> 6
A5: Seed | B5: Player | F5: Game ID | G5: Stage | H5: Slot 1 | I5: Slot 2 | J5: Winner Input | K5: MVP Input | L5: Winner | M5: Loser | N5: Completed? | O5: MVP Helper 1 | P5: MVP Helper 2 | Q5: MVP Helper 3 | R5: MVP Helper 4 | S5: MVP Helper 5 | T5: MVP Helper 6 | U5: MVP Helper 7 | V5: MVP Helper 8 | W5: MVP Helper 9
A6: =IF(1<=$G$3,1,"") -> 1 | B6: =IF(1<=$G$3,Settings!$K$3,"") -> May | F6: =IF(ROW()-5>2*$G$3-1,"","G"&(ROW()-5)) -> G1 | G6: {=IFERROR(INDEX(Lists!$L$2:$L$56,MATCH($G$3*100+(ROW()-5),Lists!$J$2:$J$56*100+Lists!$K$2:$K$56,0)),"")} -> Winners R1-1 | H6: {=_xlfn.LET(_xlpm.seq,ROW()-5,_xlpm.maxg,2*$G$3-1,_xlpm.src,IF(_xlpm.seq>_xlpm.maxg,"",IFERROR(INDEX(Lists!$M$2:$M$56,MATCH($G$3*100+_xlpm.seq,Lists!$J$2:$J$56*100+Lists!$K$2:$K$56,0)),"")),IF(_xlpm.src="","",IF(LEFT(_xlpm.src,4)="Seed",IFERROR(INDEX($B$6:$B$14,VALUE(MID(_xlpm.src,5,10))),""),IF(LEFT(_xlpm.src,2)="W:",IFERROR(INDEX($L$6:$L$21,MATCH(MID(_xlpm.src,3,50),$G$6:$G$21,0)),""),IF(LEFT(_xlpm.src,2)="L:",IFERROR(INDEX($M$6:$M$21,MATCH(MID(_xlpm.src,3,50),$G$6:$G$21,0)),""),"")))))} -> Nick | I6: {=_xlfn.LET(_xlpm.seq,ROW()-5,_xlpm.maxg,2*$G$3-1,_xlpm.src,IF(_xlpm.seq>_xlpm.maxg,"",IFERROR(INDEX(Lists!$N$2:$N$56,MATCH($G$3*100+_xlpm.seq,Lists!$J$2:$J$56*100+Lists!$K$2:$K$56,0)),"")),IF(_xlpm.src="","",IF(LEFT(_xlpm.src,4)="Seed",IFERROR(INDEX($B$6:$B$14,VALUE(MID(_xlpm.src,5,10))),""),IF(LEFT(_xlpm.src,2)="W:",IFERROR(INDEX($L$6:$L$21,MATCH(MID(_xlpm.src,3,50),$G$6:$G$21,0)),""),IF(LEFT(_xlpm.src,2)="L:",IFERROR(INDEX($M$6:$M$21,MATCH(MID(_xlpm.src,3,50),$G$6:$G$21,0)),""),"")))))} -> Donovan | J6: Nick | K6: Daisy | L6: =IF(G6="","",IF(G6="CG-2",IF(OR(H6="",I6=""),"",IF(J6<>"",J6,"")),IF(J6<>"",J6,""))) -> Nick | M6: =IF(OR(L6="",H6="",I6=""),"",IF(L6=H6,I6,H6)) -> Donovan | N6: =IF(AND(L6<>"",H6<>"",I6<>""),"Yes","") -> Yes | O6: =IF($J6="","",IFERROR(INDEX(Draft!$H$6:$N$14,1,MATCH($J6,Draft!$H$5:$N$5,0)),"")) -> Daisy | P6: =IF($J6="","",IFERROR(INDEX(Draft!$H$6:$N$14,2,MATCH($J6,Draft!$H$5:$N$5,0)),"")) -> Mii | Q6: =IF($J6="","",IFERROR(INDEX(Draft!$H$6:$N$14,3,MATCH($J6,Draft!$H$5:$N$5,0)),"")) -> Toadette | R6: =IF($J6="","",IFERROR(INDEX(Draft!$H$6:$N$14,4,MATCH($J6,Draft!$H$5:$N$5,0)),"")) -> Blue Toad | S6: =IF($J6="","",IFERROR(INDEX(Draft!$H$6:$N$14,5,MATCH($J6,Draft!$H$5:$N$5,0)),"")) -> Monty Mole | T6: =IF($J6="","",IFERROR(INDEX(Draft!$H$6:$N$14,6,MATCH($J6,Draft!$H$5:$N$5,0)),"")) -> Wario | U6: =IF($J6="","",IFERROR(INDEX(Draft!$H$6:$N$14,7,MATCH($J6,Draft!$H$5:$N$5,0)),"")) -> Wiggler | V6: =IF($J6="","",IFERROR(INDEX(Draft!$H$6:$N$14,8,MATCH($J6,Draft!$H$5:$N$5,0)),"")) -> Boomerang Bro | W6: =IF($J6="","",IFERROR(INDEX(Draft!$H$6:$N$14,9,MATCH($J6,Draft!$H$5:$N$5,0)),"")) -> Green Dry Bones
A7: =IF(2<=$G$3,2,"") -> 2 | B7: =IF(2<=$G$3,Settings!$K$4,"") -> Jason | F7: =IF(ROW()-5>2*$G$3-1,"","G"&(ROW()-5)) -> G2 | G7: {=IFERROR(INDEX(Lists!$L$2:$L$56,MATCH($G$3*100+(ROW()-5),Lists!$J$2:$J$56*100+Lists!$K$2:$K$56,0)),"")} -> Winners R1-2 | H7: {=_xlfn.LET(_xlpm.seq,ROW()-5,_xlpm.maxg,2*$G$3-1,_xlpm.src,IF(_xlpm.seq>_xlpm.maxg,"",IFERROR(INDEX(Lists!$M$2:$M$56,MATCH($G$3*100+_xlpm.seq,Lists!$J$2:$J$56*100+Lists!$K$2:$K$56,0)),"")),IF(_xlpm.src="","",IF(LEFT(_xlpm.src,4)="Seed",IFERROR(INDEX($B$6:$B$14,VALUE(MID(_xlpm.src,5,10))),""),IF(LEFT(_xlpm.src,2)="W:",IFERROR(INDEX($L$6:$L$21,MATCH(MID(_xlpm.src,3,50),$G$6:$G$21,0)),""),IF(LEFT(_xlpm.src,2)="L:",IFERROR(INDEX($M$6:$M$21,MATCH(MID(_xlpm.src,3,50),$G$6:$G$21,0)),""),"")))))} -> Aidan | I7: {=_xlfn.LET(_xlpm.seq,ROW()-5,_xlpm.maxg,2*$G$3-1,_xlpm.src,IF(_xlpm.seq>_xlpm.maxg,"",IFERROR(INDEX(Lists!$N$2:$N$56,MATCH($G$3*100+_xlpm.seq,Lists!$J$2:$J$56*100+Lists!$K$2:$K$56,0)),"")),IF(_xlpm.src="","",IF(LEFT(_xlpm.src,4)="Seed",IFERROR(INDEX($B$6:$B$14,VALUE(MID(_xlpm.src,5,10))),""),IF(LEFT(_xlpm.src,2)="W:",IFERROR(INDEX($L$6:$L$21,MATCH(MID(_xlpm.src,3,50),$G$6:$G$21,0)),""),IF(LEFT(_xlpm.src,2)="L:",IFERROR(INDEX($M$6:$M$21,MATCH(MID(_xlpm.src,3,50),$G$6:$G$21,0)),""),"")))))} -> Justin | J7: Aidan | K7: Yellow Pianta | L7: =IF(G7="","",IF(G7="CG-2",IF(OR(H7="",I7=""),"",IF(J7<>"",J7,"")),IF(J7<>"",J7,""))) -> Aidan | M7: =IF(OR(L7="",H7="",I7=""),"",IF(L7=H7,I7,H7)) -> Justin | N7: =IF(AND(L7<>"",H7<>"",I7<>""),"Yes","") -> Yes | O7: =IF($J7="","",IFERROR(INDEX(Draft!$H$6:$N$14,1,MATCH($J7,Draft!$H$5:$N$5,0)),"")) -> Mario | P7: =IF($J7="","",IFERROR(INDEX(Draft!$H$6:$N$14,2,MATCH($J7,Draft!$H$5:$N$5,0)),"")) -> Luigi | Q7: =IF($J7="","",IFERROR(INDEX(Draft!$H$6:$N$14,3,MATCH($J7,Draft!$H$5:$N$5,0)),"")) -> Dark Bones | R7: =IF($J7="","",IFERROR(INDEX(Draft!$H$6:$N$14,4,MATCH($J7,Draft!$H$5:$N$5,0)),"")) -> Pink Yoshi | S7: =IF($J7="","",IFERROR(INDEX(Draft!$H$6:$N$14,5,MATCH($J7,Draft!$H$5:$N$5,0)),"")) -> Red Magikoopa | T7: =IF($J7="","",IFERROR(INDEX(Draft!$H$6:$N$14,6,MATCH($J7,Draft!$H$5:$N$5,0)),"")) -> Blue Pianta | U7: =IF($J7="","",IFERROR(INDEX(Draft!$H$6:$N$14,7,MATCH($J7,Draft!$H$5:$N$5,0)),"")) -> Yellow Pianta | V7: =IF($J7="","",IFERROR(INDEX(Draft!$H$6:$N$14,8,MATCH($J7,Draft!$H$5:$N$5,0)),"")) -> Blue Kritter | W7: =IF($J7="","",IFERROR(INDEX(Draft!$H$6:$N$14,9,MATCH($J7,Draft!$H$5:$N$5,0)),"")) -> Blue Dry Bones
A8: =IF(3<=$G$3,3,"") -> 3 | B8: =IF(3<=$G$3,Settings!$K$5,"") -> Aidan | F8: =IF(ROW()-5>2*$G$3-1,"","G"&(ROW()-5)) -> G3 | G8: {=IFERROR(INDEX(Lists!$L$2:$L$56,MATCH($G$3*100+(ROW()-5),Lists!$J$2:$J$56*100+Lists!$K$2:$K$56,0)),"")} -> Winners R2-1 | H8: {=_xlfn.LET(_xlpm.seq,ROW()-5,_xlpm.maxg,2*$G$3-1,_xlpm.src,IF(_xlpm.seq>_xlpm.maxg,"",IFERROR(INDEX(Lists!$M$2:$M$56,MATCH($G$3*100+_xlpm.seq,Lists!$J$2:$J$56*100+Lists!$K$2:$K$56,0)),"")),IF(_xlpm.src="","",IF(LEFT(_xlpm.src,4)="Seed",IFERROR(INDEX($B$6:$B$14,VALUE(MID(_xlpm.src,5,10))),""),IF(LEFT(_xlpm.src,2)="W:",IFERROR(INDEX($L$6:$L$21,MATCH(MID(_xlpm.src,3,50),$G$6:$G$21,0)),""),IF(LEFT(_xlpm.src,2)="L:",IFERROR(INDEX($M$6:$M$21,MATCH(MID(_xlpm.src,3,50),$G$6:$G$21,0)),""),"")))))} -> May | I8: {=_xlfn.LET(_xlpm.seq,ROW()-5,_xlpm.maxg,2*$G$3-1,_xlpm.src,IF(_xlpm.seq>_xlpm.maxg,"",IFERROR(INDEX(Lists!$N$2:$N$56,MATCH($G$3*100+_xlpm.seq,Lists!$J$2:$J$56*100+Lists!$K$2:$K$56,0)),"")),IF(_xlpm.src="","",IF(LEFT(_xlpm.src,4)="Seed",IFERROR(INDEX($B$6:$B$14,VALUE(MID(_xlpm.src,5,10))),""),IF(LEFT(_xlpm.src,2)="W:",IFERROR(INDEX($L$6:$L$21,MATCH(MID(_xlpm.src,3,50),$G$6:$G$21,0)),""),IF(LEFT(_xlpm.src,2)="L:",IFERROR(INDEX($M$6:$M$21,MATCH(MID(_xlpm.src,3,50),$G$6:$G$21,0)),""),"")))))} -> Nick | J8: Nick | K8: Daisy | L8: =IF(G8="","",IF(G8="CG-2",IF(OR(H8="",I8=""),"",IF(J8<>"",J8,"")),IF(J8<>"",J8,""))) -> Nick | M8: =IF(OR(L8="",H8="",I8=""),"",IF(L8=H8,I8,H8)) -> May | N8: =IF(AND(L8<>"",H8<>"",I8<>""),"Yes","") -> Yes | O8: =IF($J8="","",IFERROR(INDEX(Draft!$H$6:$N$14,1,MATCH($J8,Draft!$H$5:$N$5,0)),"")) -> Daisy | P8: =IF($J8="","",IFERROR(INDEX(Draft!$H$6:$N$14,2,MATCH($J8,Draft!$H$5:$N$5,0)),"")) -> Mii | Q8: =IF($J8="","",IFERROR(INDEX(Draft!$H$6:$N$14,3,MATCH($J8,Draft!$H$5:$N$5,0)),"")) -> Toadette | R8: =IF($J8="","",IFERROR(INDEX(Draft!$H$6:$N$14,4,MATCH($J8,Draft!$H$5:$N$5,0)),"")) -> Blue Toad | S8: =IF($J8="","",IFERROR(INDEX(Draft!$H$6:$N$14,5,MATCH($J8,Draft!$H$5:$N$5,0)),"")) -> Monty Mole | T8: =IF($J8="","",IFERROR(INDEX(Draft!$H$6:$N$14,6,MATCH($J8,Draft!$H$5:$N$5,0)),"")) -> Wario | U8: =IF($J8="","",IFERROR(INDEX(Draft!$H$6:$N$14,7,MATCH($J8,Draft!$H$5:$N$5,0)),"")) -> Wiggler | V8: =IF($J8="","",IFERROR(INDEX(Draft!$H$6:$N$14,8,MATCH($J8,Draft!$H$5:$N$5,0)),"")) -> Boomerang Bro | W8: =IF($J8="","",IFERROR(INDEX(Draft!$H$6:$N$14,9,MATCH($J8,Draft!$H$5:$N$5,0)),"")) -> Green Dry Bones
